<mujoco model="aic_world">
  <compiler angle="radian"/>

  <option gravity="0 0 -9.8" magnetic="5.5645e-06 2.28758e-05 -4.23884e-05"/>

  <visual>
    <headlight ambient="0 0 0" diffuse="0 0 0" specular="0 0 0"/>
  </visual>

  <default>
    <default class="world_default"/>
    <default class="cable_default">
      <joint damping="0.1"/>
    </default>
  </default>

  <extension>
    <plugin plugin="mujoco.elasticity.cable">
      <instance name="composite">
        <config key="twist" value="1e2"/>
        <config key="bend" value="4e1"/>
      </instance>
    </plugin>
  </extension>

  <asset>
    <texture type="2d" colorspace="linear" name="texture_7d2d03d984e0bd4273d245008f309f6a2ab0c0d6961ab1d51b3160a265d7b5a4_floor_visual_Plane" file="7d2d03d984e0bd4273d245008f309f6a2ab0c0d6961ab1d51b3160a265d7b5a4_floor_visual_b3a94635-54d6beff6424435d3828cb4c8a1278d9ea3964b0.png"/>
    <texture type="2d" colorspace="linear" name="texture_79d083415a0beb7006489abaa2f7f67624ecb5cc84df7fd21d83dada2e2c75a0_lc_plug_visual_merged_0" file="79d083415a0beb7006489abaa2f7f67624ecb5cc84df7fd21d83dada2e2c75a0_lc_plug_visual_03dabf32-0905e8a8aa368516e682f6ec84258100cdb4efef.png"/>
    <texture type="2d" colorspace="linear" name="texture_07ae86fedcbbab3b5759a8a6e79ba15af5075968dd5eac2cb4666913710c9b1a_sfp_module_visual_Body.005" file="07ae86fedcbbab3b5759a8a6e79ba15af5075968dd5eac2cb4666913710c9b1a_sfp_module_visual_8fc63b58-7471eafc55dcb668ae68adfe70a147b363ba3be9.png"/>
    <texture type="2d" colorspace="linear" name="texture_07ae86fedcbbab3b5759a8a6e79ba15af5075968dd5eac2cb4666913710c9b1a_sfp_module_visual_Body.005_1" file="07ae86fedcbbab3b5759a8a6e79ba15af5075968dd5eac2cb4666913710c9b1a_sfp_module_visual_1f09e86a-a4dc4a72bd6e778067310898a5c179607fd78966.png"/>
    <texture type="2d" colorspace="linear" name="texture_39e0c36083c2ebca1948ca6b7f99419210f3b34232289a37761dbe25cefc0443_sc_plug_visual_merged_0" file="39e0c36083c2ebca1948ca6b7f99419210f3b34232289a37761dbe25cefc0443_sc_plug_visual_5875f865-48f62b2f4840d852c7f39a01e6c183037dc1485b.png"/>
    <material name="material_21630dbca88254236676b9eaa3d656b1a410544dc4182b3953f5492d6064c1ce_enclosure_visual_V1014952.001" class="world_default" shininess="30" rgba="0.290196 0.290196 0.290196 1"/>
    <material name="material_21630dbca88254236676b9eaa3d656b1a410544dc4182b3953f5492d6064c1ce_enclosure_visual_V1014952.001_1" class="world_default" shininess="30" rgba="0.129412 0.129412 0.133333 1"/>
    <material name="material_21630dbca88254236676b9eaa3d656b1a410544dc4182b3953f5492d6064c1ce_light_visual_Plane.001" class="world_default" shininess="30" rgba="0.5 0.5 0.5 1"/>
    <material name="material_7d2d03d984e0bd4273d245008f309f6a2ab0c0d6961ab1d51b3160a265d7b5a4_floor_visual_Plane" class="world_default" texture="texture_7d2d03d984e0bd4273d245008f309f6a2ab0c0d6961ab1d51b3160a265d7b5a4_floor_visual_Plane" shininess="30" rgba="0.5 0.5 0.5 1"/>
    <material name="material_7d2d03d984e0bd4273d245008f309f6a2ab0c0d6961ab1d51b3160a265d7b5a4_walls_visual_Curve.001" class="world_default" shininess="30" rgba="0.0196078 0.0196078 0.0196078 1"/>
    <material name="material_7d2d03d984e0bd4273d245008f309f6a2ab0c0d6961ab1d51b3160a265d7b5a4_walls_visual_merged_1" class="world_default" shininess="30" rgba="0.262745 0.262745 0.262745 1"/>
    <material name="material_7d2d03d984e0bd4273d245008f309f6a2ab0c0d6961ab1d51b3160a265d7b5a4_walls_visual_Plane.003_1" class="world_default" shininess="30" rgba="0.8 0.8 0.8 1"/>
    <material name="material_7d2d03d984e0bd4273d245008f309f6a2ab0c0d6961ab1d51b3160a265d7b5a4_walls_visual_Plane.002" class="world_default" shininess="30" rgba="0.207843 0.207843 0.207843 1"/>
    <material name="material_79d083415a0beb7006489abaa2f7f67624ecb5cc84df7fd21d83dada2e2c75a0_lc_plug_visual_merged_0" class="world_default" texture="texture_79d083415a0beb7006489abaa2f7f67624ecb5cc84df7fd21d83dada2e2c75a0_lc_plug_visual_merged_0" shininess="30" rgba="0.5 0.5 0.5 1"/>
    <material name="material_07ae86fedcbbab3b5759a8a6e79ba15af5075968dd5eac2cb4666913710c9b1a_sfp_module_visual_Body.005" class="world_default" texture="texture_07ae86fedcbbab3b5759a8a6e79ba15af5075968dd5eac2cb4666913710c9b1a_sfp_module_visual_Body.005" shininess="30" rgba="0.5 0.5 0.5 1"/>
    <material name="material_07ae86fedcbbab3b5759a8a6e79ba15af5075968dd5eac2cb4666913710c9b1a_sfp_module_visual_Body.005_1" class="world_default" texture="texture_07ae86fedcbbab3b5759a8a6e79ba15af5075968dd5eac2cb4666913710c9b1a_sfp_module_visual_Body.005_1" shininess="30" rgba="0.5 0.5 0.5 1"/>
    <material name="material_39e0c36083c2ebca1948ca6b7f99419210f3b34232289a37761dbe25cefc0443_sc_plug_visual_merged_0" class="world_default" texture="texture_39e0c36083c2ebca1948ca6b7f99419210f3b34232289a37761dbe25cefc0443_sc_plug_visual_merged_0" shininess="30" rgba="0.5 0.5 0.5 1"/>
    <material name="material_19f4a95a97b71184a4988be290e52b57fe33862b52d650c82c5d8bc673fc5603_base_visual_ISO_4762_-_M3_x_8.019" class="world_default" shininess="30" rgba="0.0352941 0.0352941 0.0313726 1"/>
    <material name="material_19f4a95a97b71184a4988be290e52b57fe33862b52d650c82c5d8bc673fc5603_base_visual_ISO_4762_-_M3_x_8.019_1" class="world_default" shininess="30" rgba="0.0313726 0.0313726 0.0313726 1"/>
    <material name="material_19f4a95a97b71184a4988be290e52b57fe33862b52d650c82c5d8bc673fc5603_base_visual_ISO_4762_-_M3_x_8.019_2" class="world_default" shininess="30" rgba="0.215686 0 0.215686 1"/>
    <material name="material_0caf49b143bca9a0c9a13d66d2f75335ec2e74c5bba5cfb7bf0c411aed5bc2cd_sfp_mount_visual_ISO_4762_-_M2_x_8.011" class="world_default" shininess="30" rgba="0.0313726 0.0313726 0.0313726 1"/>
    <material name="material_0caf49b143bca9a0c9a13d66d2f75335ec2e74c5bba5cfb7bf0c411aed5bc2cd_sfp_mount_visual_ISO_4762_-_M2_x_8.011_1" class="world_default" shininess="30" rgba="0.0352941 0.0352941 0.0313726 1"/>
    <mesh name="21630dbca88254236676b9eaa3d656b1a410544dc4182b3953f5492d6064c1ce_enclosure_visual_V1014952.001" class="world_default" content_type="model/obj" file="21630dbca88254236676b9eaa3d656b1a410544dc4182b3953f5492d6064c1ce_enclosure_visual_V1014952.001-c990efe7b9dfe87aa065fd6eb3960ce051ae2aef.obj" inertia="shell"/>
    <mesh name="21630dbca88254236676b9eaa3d656b1a410544dc4182b3953f5492d6064c1ce_enclosure_visual_V1014952.001_1" class="world_default" content_type="model/obj" file="21630dbca88254236676b9eaa3d656b1a410544dc4182b3953f5492d6064c1ce_enclosure_visual_V1014952.001_1-807e07de06af157c84b994a232617507a7059420.obj" inertia="shell"/>
    <mesh name="21630dbca88254236676b9eaa3d656b1a410544dc4182b3953f5492d6064c1ce_light_visual_Plane.001" class="world_default" content_type="model/obj" file="21630dbca88254236676b9eaa3d656b1a410544dc4182b3953f5492d6064c1ce_light_visual_Plane.001-a8a774a80bc239d73769a498eae528b206eebcb0.obj" inertia="shell"/>
    <mesh name="7d2d03d984e0bd4273d245008f309f6a2ab0c0d6961ab1d51b3160a265d7b5a4_floor_visual_Plane" class="world_default" content_type="model/obj" file="7d2d03d984e0bd4273d245008f309f6a2ab0c0d6961ab1d51b3160a265d7b5a4_floor_visual_Plane-4dc7f6150ad7c239769a0860a01efb2015657aea.obj" inertia="shell"/>
    <mesh name="7d2d03d984e0bd4273d245008f309f6a2ab0c0d6961ab1d51b3160a265d7b5a4_walls_visual_Curve.001" class="world_default" content_type="model/obj" file="7d2d03d984e0bd4273d245008f309f6a2ab0c0d6961ab1d51b3160a265d7b5a4_walls_visual_Curve.001-4d7c79ac2e958832fdb15589262141ca1b80d3a5.obj" inertia="shell"/>
    <mesh name="7d2d03d984e0bd4273d245008f309f6a2ab0c0d6961ab1d51b3160a265d7b5a4_walls_visual_merged_1" class="world_default" content_type="model/obj" file="7d2d03d984e0bd4273d245008f309f6a2ab0c0d6961ab1d51b3160a265d7b5a4_walls_visual_merged_1-359a22140d528747936e80bedf90e1437a177a9f.obj" inertia="shell"/>
    <mesh name="7d2d03d984e0bd4273d245008f309f6a2ab0c0d6961ab1d51b3160a265d7b5a4_walls_visual_Plane.003_1" class="world_default" content_type="model/obj" file="7d2d03d984e0bd4273d245008f309f6a2ab0c0d6961ab1d51b3160a265d7b5a4_walls_visual_Plane.003_1-cd05ed21fa19a2784fb772d7519abf7c31c8b85f.obj" inertia="shell"/>
    <mesh name="7d2d03d984e0bd4273d245008f309f6a2ab0c0d6961ab1d51b3160a265d7b5a4_walls_visual_Plane.002" class="world_default" content_type="model/obj" file="7d2d03d984e0bd4273d245008f309f6a2ab0c0d6961ab1d51b3160a265d7b5a4_walls_visual_Plane.002-ee4f781765eec46c2256d941981732d4b1857f24.obj" inertia="shell"/>
    <mesh name="79d083415a0beb7006489abaa2f7f67624ecb5cc84df7fd21d83dada2e2c75a0_lc_plug_visual_merged_0" class="world_default" content_type="model/obj" file="79d083415a0beb7006489abaa2f7f67624ecb5cc84df7fd21d83dada2e2c75a0_lc_plug_visual_merged_0-fdaf59710fc3cc118a7df05add4ff4205edda4ef.obj" inertia="shell"/>
    <mesh name="07ae86fedcbbab3b5759a8a6e79ba15af5075968dd5eac2cb4666913710c9b1a_sfp_module_visual_Body.005" class="world_default" content_type="model/obj" file="07ae86fedcbbab3b5759a8a6e79ba15af5075968dd5eac2cb4666913710c9b1a_sfp_module_visual_Body.005-f93147e1e403de321fb70c06a4b1e00f20feb9fd.obj" inertia="shell"/>
    <mesh name="07ae86fedcbbab3b5759a8a6e79ba15af5075968dd5eac2cb4666913710c9b1a_sfp_module_visual_Body.005_1" class="world_default" content_type="model/obj" file="07ae86fedcbbab3b5759a8a6e79ba15af5075968dd5eac2cb4666913710c9b1a_sfp_module_visual_Body.005_1-4af964a95522e2593eb6381eca4f09ef239782c7.obj" inertia="shell"/>
    <mesh name="39e0c36083c2ebca1948ca6b7f99419210f3b34232289a37761dbe25cefc0443_sc_plug_visual_merged_0" class="world_default" content_type="model/obj" file="39e0c36083c2ebca1948ca6b7f99419210f3b34232289a37761dbe25cefc0443_sc_plug_visual_merged_0-67f94accf247f722dd4954d7448d7956402901f2.obj" inertia="shell"/>
    <mesh name="19f4a95a97b71184a4988be290e52b57fe33862b52d650c82c5d8bc673fc5603_base_visual_ISO_4762_-_M3_x_8.019" class="world_default" content_type="model/obj" file="19f4a95a97b71184a4988be290e52b57fe33862b52d650c82c5d8bc673fc5603_base_visual_ISO_4762_-_M3_x_8.019-f814bb518c42769543ab6246809f3fe4af5c2b64.obj" inertia="shell"/>
    <mesh name="19f4a95a97b71184a4988be290e52b57fe33862b52d650c82c5d8bc673fc5603_base_visual_ISO_4762_-_M3_x_8.019_1" class="world_default" content_type="model/obj" file="19f4a95a97b71184a4988be290e52b57fe33862b52d650c82c5d8bc673fc5603_base_visual_ISO_4762_-_M3_x_8.019_1-0b276ba9910a7642121235b62d2afc47c3995782.obj" inertia="shell"/>
    <mesh name="19f4a95a97b71184a4988be290e52b57fe33862b52d650c82c5d8bc673fc5603_base_visual_ISO_4762_-_M3_x_8.019_2" class="world_default" content_type="model/obj" file="19f4a95a97b71184a4988be290e52b57fe33862b52d650c82c5d8bc673fc5603_base_visual_ISO_4762_-_M3_x_8.019_2-7b96569be9572803417c5650ee83c9c883b44191.obj" inertia="shell"/>
    <mesh name="0caf49b143bca9a0c9a13d66d2f75335ec2e74c5bba5cfb7bf0c411aed5bc2cd_sfp_mount_visual_ISO_4762_-_M2_x_8.011" class="world_default" content_type="model/obj" file="0caf49b143bca9a0c9a13d66d2f75335ec2e74c5bba5cfb7bf0c411aed5bc2cd_sfp_mount_visual_ISO_4762_-_M2_x_8.011-e79a298280ce559f60558a5df64e118c814f63e4.obj" inertia="shell"/>
    <mesh name="0caf49b143bca9a0c9a13d66d2f75335ec2e74c5bba5cfb7bf0c411aed5bc2cd_sfp_mount_visual_ISO_4762_-_M2_x_8.011_1" class="world_default" content_type="model/obj" file="0caf49b143bca9a0c9a13d66d2f75335ec2e74c5bba5cfb7bf0c411aed5bc2cd_sfp_mount_visual_ISO_4762_-_M2_x_8.011_1-3a79ef8883f6645921d3fa2c67cf381141e6ea26.obj" inertia="shell"/>
  </asset>

  <worldbody>
    <light name="enclosure_light" class="world_default" pos="0 0 2.5" dir="0 0 -1" intensity="0.4" range="2" attenuation="1 0.01 0.001" cutoff="114.592" exponent="0.993023" diffuse="1 1 1" specular="0.1 0.1 0.1"/>
    <light name="ceiling_01" class="world_default" pos="2 2 6" dir="0 0 -1" intensity="2" range="9" castshadow="false" attenuation="1 0.01 0.001" cutoff="360" diffuse="1 1 1" specular="0.1 0.1 0.1"/>
    <light name="ceiling_02" class="world_default" pos="-2 -2 6" dir="0 0 -1" intensity="2" range="9" castshadow="false" attenuation="1 0.01 0.001" cutoff="360" diffuse="1 1 1" specular="0.1 0.1 0.1"/>
    <body name="enclosure_link">
      <inertial pos="0 0 0" mass="1" diaginertia="1 1 1"/>
      <geom name="v1015026001_collider_box" class="world_default" size="0.75 0.569492 0.75" pos="-0.010998 0.009283 0.569706" quat="-1.22475e-07 1.22474e-07 -0.707107 -0.707107" type="box" group="3"/>
      <geom name="v1015028001_collider_box" class="world_default" size="0.0254 0.0254 1.25" pos="0.713602 0.733883 1.3292" quat="1.73205e-07 0 0 -1" type="box" group="3"/>
      <geom name="v1015013001_collider_box" class="world_default" size="0.0304 0.75 0.75" pos="-0.010998 0.009283 2.5488" quat="0.707107 0 -0.707107 0" type="box" group="3"/>
      <geom name="v1015027_collider_box" class="world_default" size="0.0254 0.0254 1.25" pos="-0.735598 0.733883 1.3292" quat="1.73205e-07 0 0 -1" type="box" group="3"/>
      <geom name="v1015029_collider_box" class="world_default" size="0.0254 0.0254 1.25" pos="-0.735598 -0.715317 1.3292" quat="0 1.73205e-07 -1 -1.73205e-07" type="box" group="3"/>
      <geom name="v1015030_collider_box" class="world_default" size="0.0254 0.0254 1.25" pos="0.713602 -0.715317 1.3292" quat="1.73205e-07 0 0 -1" type="box" group="3"/>
      <geom name="enclosure_visual" class="world_default" type="mesh" contype="0" conaffinity="0" material="material_21630dbca88254236676b9eaa3d656b1a410544dc4182b3953f5492d6064c1ce_enclosure_visual_V1014952.001" mesh="21630dbca88254236676b9eaa3d656b1a410544dc4182b3953f5492d6064c1ce_enclosure_visual_V1014952.001"/>
      <geom name="enclosure_visual_0" class="world_default" type="mesh" contype="0" conaffinity="0" material="material_21630dbca88254236676b9eaa3d656b1a410544dc4182b3953f5492d6064c1ce_enclosure_visual_V1014952.001_1" mesh="21630dbca88254236676b9eaa3d656b1a410544dc4182b3953f5492d6064c1ce_enclosure_visual_V1014952.001_1"/>
      <geom name="light_visual" class="world_default" type="mesh" contype="0" conaffinity="0" material="material_21630dbca88254236676b9eaa3d656b1a410544dc4182b3953f5492d6064c1ce_light_visual_Plane.001" mesh="21630dbca88254236676b9eaa3d656b1a410544dc4182b3953f5492d6064c1ce_light_visual_Plane.001"/>
    </body>
    <body name="enclosure_walls_link">
      <inertial pos="0 0 0" mass="1" diaginertia="1 1 1"/>
      <geom name="v1015062006_collider_box" class="world_default" size="0.0250005 0.6796 0.6892" pos="-0.010998 0.734284 1.8288" quat="0.5 0.5 -0.5 -0.5" type="box" group="3"/>
      <geom name="v1015062005_collider_box" class="world_default" size="0.6892 0.6796 0.025" pos="-0.735998 0.009283 1.8288" quat="0.5 0.5 -0.5 -0.5" type="box" group="3"/>
      <geom name="v1015062007_collider_box" class="world_default" size="0.025 0.6846 0.6892" pos="-0.010998 -0.715717 1.8338" quat="0.5 0.5 -0.5 -0.5" type="box" group="3"/>
      <geom name="v1015062008_collider_box" class="world_default" size="0.6892 0.6846 0.025" pos="0.714002 0.009283 1.8338" quat="0.5 0.5 -0.5 -0.5" type="box" group="3"/>
    </body>
    <body name="floor_link">
      <inertial pos="0 0 0" mass="1" diaginertia="1 1 1"/>
      <geom name="floor_cylinder" class="world_default" size="5 5 1" type="plane" group="3"/>
      <geom name="floor_visual" class="world_default" type="mesh" contype="0" conaffinity="0" material="material_7d2d03d984e0bd4273d245008f309f6a2ab0c0d6961ab1d51b3160a265d7b5a4_floor_visual_Plane" mesh="7d2d03d984e0bd4273d245008f309f6a2ab0c0d6961ab1d51b3160a265d7b5a4_floor_visual_Plane"/>
      <geom name="walls_visual" class="world_default" type="mesh" contype="0" conaffinity="0" material="material_7d2d03d984e0bd4273d245008f309f6a2ab0c0d6961ab1d51b3160a265d7b5a4_walls_visual_Curve.001" mesh="7d2d03d984e0bd4273d245008f309f6a2ab0c0d6961ab1d51b3160a265d7b5a4_walls_visual_Curve.001"/>
      <geom name="walls_visual_0" class="world_default" type="mesh" contype="0" conaffinity="0" material="material_7d2d03d984e0bd4273d245008f309f6a2ab0c0d6961ab1d51b3160a265d7b5a4_walls_visual_merged_1" mesh="7d2d03d984e0bd4273d245008f309f6a2ab0c0d6961ab1d51b3160a265d7b5a4_walls_visual_merged_1"/>
      <geom name="walls_visual_1" class="world_default" type="mesh" contype="0" conaffinity="0" material="material_7d2d03d984e0bd4273d245008f309f6a2ab0c0d6961ab1d51b3160a265d7b5a4_walls_visual_Plane.003_1" mesh="7d2d03d984e0bd4273d245008f309f6a2ab0c0d6961ab1d51b3160a265d7b5a4_walls_visual_Plane.003_1"/>
      <geom name="walls_visual_2" class="world_default" type="mesh" contype="0" conaffinity="0" material="material_7d2d03d984e0bd4273d245008f309f6a2ab0c0d6961ab1d51b3160a265d7b5a4_walls_visual_Plane.002" mesh="7d2d03d984e0bd4273d245008f309f6a2ab0c0d6961ab1d51b3160a265d7b5a4_walls_visual_Plane.002"/>
    </body>
    <body name="cable_end_0" childclass="cable_default" pos="0.171400 0.020606 1.511889" quat="0.712741 0.312130 -0.052173 0.625982">
      <freejoint name="cable_end_0_free"/>
      <inertial pos="0 0 0" mass="0.0025" diaginertia="1e-6 1e-6 1e-6"/>
      <geom name="base_vis" class="world_default" size="0.002" contype="0" conaffinity="0"/>
      <body name="cable_connection_0" pos="1.25047e-08 8.16282e-08 -1.95829e-07" quat="0.568653 -0.7585 -0.304364 -0.0931319">
        <inertial pos="0 0 0" mass="0.01" diaginertia="1e-6 1e-6 1e-6"/>
        <joint name="joint_connection_end_0" class="world_default" pos="0 0 0" type="ball" damping="0.2"/>
        <geom name="visual_0_0" class="world_default" size="0.001 0.00367636" pos="-0.00367636 0.00425 0" quat="0.673802 0.214463 0.673798 -0.214461" type="cylinder" contype="0" conaffinity="0"/>
        <geom name="visual_1_0" class="world_default" size="0.001 0.00367636" pos="-0.00367636 -0.00425 0" quat="0.673802 -0.214463 0.673798 0.214461" type="cylinder" contype="0" conaffinity="0"/>
        <body name="link_1" pos="0.00491422 0.0231421 -0.00403678" quat="0.105615 -0.279044 -0.711501 -0.636197">
          <inertial pos="0 0 0" mass="0.0025" diaginertia="1e-6 1e-6 1e-6"/>
          <joint name="joint_end_0" pos="0 0 -0.024" type="ball"/>
          <geom name="link_1_collision" size="0.002 0.018" pos="0 0 0.006" type="cylinder" group="3"/>
          <geom name="sphere_1_collision" size="0.002" pos="0 0 0.024" group="3"/>
          <geom name="link_1_vis" size="0.002 0.024" type="cylinder" contype="0" conaffinity="0"/>
          <geom name="sphere_1_vis" size="0.002" pos="0 0 0.024" contype="0" conaffinity="0"/>
          <body name="link_2" pos="0.00608341 -0.00758186 0.0459437" quat="0.978077 0.158393 0.133259 -0.0227629">
            <inertial pos="0 0 0" mass="0.0025" diaginertia="1e-6 1e-6 1e-6"/>
            <joint name="joint_1" pos="0 0 -0.024" type="ball"/>
            <geom name="link_2_collision" size="0.002 0.024" type="cylinder" group="3"/>
            <geom name="sphere_2_collision" size="0.002" pos="0 0 0.024" group="3"/>
            <geom name="link_2_vis" size="0.002 0.024" type="cylinder" contype="0" conaffinity="0"/>
            <geom name="sphere_2_vis" size="0.002" pos="0 0 0.024" contype="0" conaffinity="0"/>
            <body name="link_3" pos="0.000343805 -0.00668268 0.0470486" quat="0.989784 0.140421 0.0104012 -0.0223824">
              <inertial pos="0 0 0" mass="0.0025" diaginertia="1e-6 1e-6 1e-6"/>
              <joint name="joint_2" pos="0 0 -0.024" type="ball"/>
              <geom name="link_3_collision" size="0.002 0.024" type="cylinder" group="3"/>
              <geom name="sphere_3_collision" size="0.002" pos="0 0 0.024" group="3"/>
              <geom name="link_3_vis" size="0.002 0.024" type="cylinder" contype="0" conaffinity="0"/>
              <geom name="sphere_3_vis" size="0.002" pos="0 0 0.024" contype="0" conaffinity="0"/>
              <body name="link_4" pos="-0.0022296 -0.00468828 0.0474319" quat="0.993743 0.0994111 -0.044222 -0.0252245">
                <inertial pos="0 0 0" mass="0.0025" diaginertia="1e-6 1e-6 1e-6"/>
                <joint name="joint_3" pos="0 0 -0.024" type="ball"/>
                <geom name="link_4_collision" size="0.002 0.024" type="cylinder" group="3"/>
                <geom name="sphere_4_collision" size="0.002" pos="0 0 0.024" group="3"/>
                <geom name="link_4_vis" size="0.002 0.024" type="cylinder" contype="0" conaffinity="0"/>
                <geom name="sphere_4_vis" size="0.002" pos="0 0 0.024" contype="0" conaffinity="0"/>
                <body name="link_5" pos="-0.00370041 -0.00315661 0.0475025" quat="0.99397 0.0692135 -0.0747307 -0.0405953">
                  <inertial pos="0 0 0" mass="0.0025" diaginertia="1e-6 1e-6 1e-6"/>
                  <joint name="joint_4" pos="0 0 -0.024" type="ball"/>
                  <geom name="link_5_collision" size="0.002 0.024" type="cylinder" group="3"/>
                  <geom name="sphere_5_collision" size="0.002" pos="0 0 0.024" group="3"/>
                  <geom name="link_5_vis" size="0.002 0.024" type="cylinder" contype="0" conaffinity="0"/>
                  <geom name="sphere_5_vis" size="0.002" pos="0 0 0.024" contype="0" conaffinity="0"/>
                  <body name="link_6" pos="-0.00400972 -0.0018031 0.0475941" quat="0.993712 0.04303 -0.0813204 -0.0638035">
                    <inertial pos="0 0 0" mass="0.0025" diaginertia="1e-6 1e-6 1e-6"/>
                    <joint name="joint_5" pos="0 0 -0.024" type="ball"/>
                    <geom name="link_6_collision" size="0.002 0.024" type="cylinder" group="3"/>
                    <geom name="sphere_6_collision" size="0.002" pos="0 0 0.024" group="3"/>
                    <geom name="link_6_vis" size="0.002 0.024" type="cylinder" contype="0" conaffinity="0"/>
                    <geom name="sphere_6_vis" size="0.002" pos="0 0 0.024" contype="0" conaffinity="0"/>
                    <body name="link_7" pos="-0.00351767 -0.000710191 0.0477308" quat="0.993356 0.0212091 -0.0719119 -0.0873041">
                      <inertial pos="0 0 0" mass="0.0025" diaginertia="1e-6 1e-6 1e-6"/>
                      <joint name="joint_6" pos="0 0 -0.024" type="ball"/>
                      <geom name="link_7_collision" size="0.002 0.024" type="cylinder" group="3"/>
                      <geom name="sphere_7_collision" size="0.002" pos="0 0 0.024" group="3"/>
                      <geom name="link_7_vis" size="0.002 0.024" type="cylinder" contype="0" conaffinity="0"/>
                      <geom name="sphere_7_vis" size="0.002" pos="0 0 0.024" contype="0" conaffinity="0"/>
                      <body name="link_8" pos="-0.00241602 0.000201002 0.047878" quat="0.993427 0.00100338 -0.0505653 -0.102685">
                        <inertial pos="0 0 0" mass="0.0025" diaginertia="1e-6 1e-6 1e-6"/>
                        <joint name="joint_7" pos="0 0 -0.024" type="ball"/>
                        <geom name="link_8_collision" size="0.002 0.024" type="cylinder" group="3"/>
                        <geom name="sphere_8_collision" size="0.002" pos="0 0 0.024" group="3"/>
                        <geom name="link_8_vis" size="0.002 0.024" type="cylinder" contype="0" conaffinity="0"/>
                        <geom name="sphere_8_vis" size="0.002" pos="0 0 0.024" contype="0" conaffinity="0"/>
                        <body name="link_9" pos="-0.00117212 0.0010058 0.0479515" quat="0.993968 -0.0182862 -0.0264966 -0.104842">
                          <inertial pos="0 0 0" mass="0.0025" diaginertia="1e-6 1e-6 1e-6"/>
                          <joint name="joint_8" pos="0 0 -0.024" type="ball"/>
                          <geom name="link_9_collision" size="0.002 0.024" type="cylinder" group="3"/>
                          <geom name="sphere_9_collision" size="0.002" pos="0 0 0.024" group="3"/>
                          <geom name="link_9_vis" size="0.002 0.024" type="cylinder" contype="0" conaffinity="0"/>
                          <geom name="sphere_9_vis" size="0.002" pos="0 0 0.024" contype="0" conaffinity="0"/>
                          <body name="link_10" pos="-0.000282197 0.00176883 0.0479333" quat="0.994692 -0.0361244 -0.00940201 -0.0958879">
                            <inertial pos="0 0 0" mass="0.0025" diaginertia="1e-6 1e-6 1e-6"/>
                            <joint name="joint_9" pos="0 0 -0.024" type="ball"/>
                            <geom name="link_10_collision" size="0.002 0.024" type="cylinder" group="3"/>
                            <geom name="sphere_10_collision" size="0.002" pos="0 0 0.024" group="3"/>
                            <geom name="link_10_vis" size="0.002 0.024" type="cylinder" contype="0" conaffinity="0"/>
                            <geom name="sphere_10_vis" size="0.002" pos="0 0 0.024" contype="0" conaffinity="0"/>
                            <body name="link_11" pos="0.0012752 0.00268708 0.0478161" quat="0.993821 -0.0583049 0.0213245 -0.0920072">
                              <inertial pos="0 0 0" mass="0.0025" diaginertia="1e-6 1e-6 1e-6"/>
                              <joint name="joint_10" pos="0 0 -0.024" type="ball"/>
                              <geom name="link_11_collision" size="0.002 0.024" type="cylinder" group="3"/>
                              <geom name="sphere_11_collision" size="0.002" pos="0 0 0.024" group="3"/>
                              <geom name="link_11_vis" size="0.002 0.024" type="cylinder" contype="0" conaffinity="0"/>
                              <geom name="sphere_11_vis" size="0.002" pos="0 0 0.024" contype="0" conaffinity="0"/>
                              <body name="link_12" pos="0.00327072 0.00422971 0.0473986" quat="0.991317 -0.0932098 0.0622678 -0.0687446">
                                <inertial pos="0 0 0" mass="0.0025" diaginertia="1e-6 1e-6 1e-6"/>
                                <joint name="joint_11" pos="0 0 -0.024" type="ball"/>
                                <geom name="link_12_collision" size="0.002 0.024" type="cylinder" group="3"/>
                                <geom name="sphere_12_collision" size="0.002" pos="0 0 0.024" group="3"/>
                                <geom name="link_12_vis" size="0.002 0.024" type="cylinder" contype="0" conaffinity="0"/>
                                <geom name="sphere_12_vis" size="0.002" pos="0 0 0.024" contype="0" conaffinity="0"/>
                                <body name="link_13" pos="0.00482261 0.00599302 0.0467345" quat="0.985833 -0.13074 0.0963345 -0.0419445">
                                  <inertial pos="0 0 0" mass="0.0025" diaginertia="1e-6 1e-6 1e-6"/>
                                  <joint name="joint_12" pos="0 0 -0.024" type="ball"/>
                                  <geom name="link_13_collision" size="0.002 0.024" type="cylinder" group="3"/>
                                  <geom name="sphere_13_collision" size="0.002" pos="0 0 0.024" group="3"/>
                                  <geom name="link_13_vis" size="0.002 0.024" type="cylinder" contype="0" conaffinity="0"/>
                                  <geom name="sphere_13_vis" size="0.002" pos="0 0 0.024" contype="0" conaffinity="0"/>
                                  <body name="link_14" pos="0.00591403 0.00751494 0.0460132" quat="0.978954 -0.161892 0.123267 -0.0156344">
                                    <inertial pos="0 0 0" mass="0.0025" diaginertia="1e-6 1e-6 1e-6"/>
                                    <joint name="joint_13" pos="0 0 -0.024" type="ball"/>
                                    <geom name="link_14_collision" size="0.002 0.024" type="cylinder" group="3"/>
                                    <geom name="sphere_14_collision" size="0.002" pos="0 0 0.024" group="3"/>
                                    <geom name="link_14_vis" size="0.002 0.024" type="cylinder" contype="0" conaffinity="0"/>
                                    <geom name="sphere_14_vis" size="0.002" pos="0 0 0.024" contype="0" conaffinity="0"/>
                                    <body name="link_15" pos="0.00664439 0.00819207 0.0455587" quat="0.974202 -0.174008 0.14349 0.00795143">
                                      <inertial pos="0 0 0" mass="0.0025" diaginertia="1e-6 1e-6 1e-6"/>
                                      <joint name="joint_14" pos="0 0 -0.024" type="ball"/>
                                      <geom name="link_15_collision" size="0.002 0.024" type="cylinder" group="3"/>
                                      <geom name="sphere_15_collision" size="0.002" pos="0 0 0.024" group="3"/>
                                      <geom name="link_15_vis" size="0.002 0.024" type="cylinder" contype="0" conaffinity="0"/>
                                      <geom name="sphere_15_vis" size="0.002" pos="0 0 0.024" contype="0" conaffinity="0"/>
                                      <body name="link_16" pos="0.00692301 0.00767899 0.0456603" quat="0.974941 -0.159938 0.152309 0.026676">
                                        <inertial pos="0 0 0" mass="0.0025" diaginertia="1e-6 1e-6 1e-6"/>
                                        <joint name="joint_15" pos="0 0 -0.024" type="ball"/>
                                        <geom name="link_16_collision" size="0.002 0.024" type="cylinder" group="3"/>
                                        <geom name="sphere_16_collision" size="0.002" pos="0 0 0.024" group="3"/>
                                        <geom name="link_16_vis" size="0.002 0.024" type="cylinder" contype="0" conaffinity="0"/>
                                        <geom name="sphere_16_vis" size="0.002" pos="0 0 0.024" contype="0" conaffinity="0"/>
                                        <body name="link_17" pos="0.00681244 0.00604806 0.0462056" quat="0.980344 -0.122562 0.149622 0.038944">
                                          <inertial pos="0 0 0" mass="0.0025" diaginertia="1e-6 1e-6 1e-6"/>
                                          <joint name="joint_16" pos="0 0 -0.024" type="ball"/>
                                          <geom name="link_17_collision" size="0.002 0.024" type="cylinder" group="3"/>
                                          <geom name="sphere_17_collision" size="0.002" pos="0 0 0.024" group="3"/>
                                          <geom name="link_17_vis" size="0.002 0.024" type="cylinder" contype="0" conaffinity="0"/>
                                          <geom name="sphere_17_vis" size="0.002" pos="0 0 0.024" contype="0" conaffinity="0"/>
                                          <body name="link_18" pos="0.00640867 0.00357157 0.0468514" quat="0.987016 -0.0693119 0.138307 0.0431988">
                                            <inertial pos="0 0 0" mass="0.0025" diaginertia="1e-6 1e-6 1e-6"/>
                                            <joint name="joint_17" pos="0 0 -0.024" type="ball"/>
                                            <geom name="link_18_collision" size="0.002 0.024" type="cylinder" group="3"/>
                                            <geom name="sphere_18_collision" size="0.002" pos="0 0 0.024" group="3"/>
                                            <geom name="link_18_vis" size="0.002 0.024" type="cylinder" contype="0" conaffinity="0"/>
                                            <geom name="sphere_18_vis" size="0.002" pos="0 0 0.024" contype="0" conaffinity="0"/>
                                            <body name="link_19" pos="0.00636467 0.00138148 0.0471004" quat="0.98985 -0.0239307 0.134876 0.0378613">
                                              <inertial pos="0 0 0" mass="0.0025" diaginertia="1e-6 1e-6 1e-6"/>
                                              <joint name="joint_18" pos="0 0 -0.024" type="ball"/>
                                              <geom name="link_19_collision" size="0.002 0.024" type="cylinder" group="3"/>
                                              <geom name="sphere_19_collision" size="0.002" pos="0 0 0.024" group="3"/>
                                              <geom name="link_19_vis" size="0.002 0.024" type="cylinder" contype="0" conaffinity="0"/>
                                              <geom name="sphere_19_vis" size="0.002" pos="0 0 0.024" contype="0" conaffinity="0"/>
                                              <body name="link_20" pos="0.0058536 -0.00106221 0.0472531" quat="0.991782 0.0257326 0.122227 0.0276918">
                                                <inertial pos="0 0 0" mass="0.0025" diaginertia="1e-6 1e-6 1e-6"/>
                                                <joint name="joint_19" pos="0 0 -0.024" type="ball"/>
                                                <geom name="link_20_collision" size="0.002 0.024" type="cylinder" group="3"/>
                                                <geom name="sphere_20_collision" size="0.002" pos="0 0 0.024" group="3"/>
                                                <geom name="link_20_vis" size="0.002 0.024" type="cylinder" contype="0" conaffinity="0"/>
                                                <geom name="sphere_20_vis" size="0.002" pos="0 0 0.024" contype="0" conaffinity="0"/>
                                                <body name="cable_connection_1" pos="1.11508e-06 -4.07664e-07 0.0240002" quat="0.776048 0.0593118 -0.626596 -0.0401108">
                                                  <inertial pos="0 0 0" mass="0.01" diaginertia="4e-4 4e-4 4e-4"/>
                                                  <joint name="joint_connection_end_1" class="world_default" pos="0 0 0" type="ball"/>
                                                  <geom name="collision_0" class="world_default" size="0.001 0.00180278" pos="0.00180278 -0.002 0" quat="0.676768 0.204909 0.676764 -0.204908" type="cylinder" group="3"/>
                                                  <geom name="collision_1" class="world_default" size="0.001 0.00180278" pos="0.00180278 0.002 0" quat="0.676768 -0.204909 0.676764 0.204908" type="cylinder" group="3"/>
                                                  <geom name="visual_0" class="world_default" size="0.001 0.00180278" pos="0.00180278 -0.002 0" quat="0.676768 0.204909 0.676764 -0.204908" type="cylinder" contype="0" conaffinity="0"/>
                                                  <geom name="visual_1" class="world_default" size="0.001 0.00180278" pos="0.00180278 0.002 0" quat="0.676768 -0.204909 0.676764 0.204908" type="cylinder" contype="0" conaffinity="0"/>
                                                  <body name="lc_plug_link" pos="0.041 3.9192e-08 1.53756e-08" quat="0.707109 7.32254e-08 -1.14792e-08 -0.707104">
                                                    <inertial pos="0 -0.00428702 8.58528e-05" quat="0.499139 0.500859 -0.500859 0.499139" mass="0.01" diaginertia="1.82581e-06 1.73585e-06 1.30866e-07"/>
                                                    <geom name="cube_collider_box.003" class="world_default" size="0.00225 0.00225 0.01" pos="0.003125 0.0097 0" quat="0.5 -0.5 0.5 0.5" type="box" group="3"/>
                                                    <geom name="cube_collider_box.002" class="world_default" size="0.00225 0.00225 0.01" pos="-0.003125 0.0097 0" quat="0.5 -0.5 0.5 0.5" type="box" group="3"/>
                                                    <geom name="cube001_collider_box.003" class="world_default" size="0.0061765 0.0028 0.001625" pos="0 0.002503 0.001434" quat="-1.73205e-07 0 1 0" type="box" group="3"/>
                                                    <geom name="cube001_collider_box.002" class="world_default" size="0.003325 0.0028 0.003016" pos="0 0.002503 -0.000413" quat="-1.73205e-07 0 1 0" type="box" group="3"/>
                                                    <geom name="cylinder001_collider_cylinder.001" class="world_default" size="0.000625 0.001502" pos="0.003125 0.0197 0" quat="0.707107 0.707107 0 0" type="cylinder" group="3"/>
                                                    <geom name="cylinder_collider_cylinder.001" class="world_default" size="0.000625 0.001502" pos="-0.003125 0.0197 0" quat="0.707107 0.707107 0 0" type="cylinder" group="3"/>
                                                    <geom name="1af02-003-ma2_collider_cylinder" class="world_default" size="0.002794 0.014351" pos="0.003125 -0.014628 0" quat="0.707107 -0.707107 0 0" type="cylinder" group="3"/>
                                                    <geom name="1af02-003-ma2001_collider_cylinder" class="world_default" size="0.002794 0.014351" pos="-0.003125 -0.014628 0" quat="0.707107 -0.707107 0 0" type="cylinder" group="3"/>
                                                    <geom name="lc_plug_visual" class="world_default" type="mesh" contype="0" conaffinity="0" material="material_79d083415a0beb7006489abaa2f7f67624ecb5cc84df7fd21d83dada2e2c75a0_lc_plug_visual_merged_0" mesh="79d083415a0beb7006489abaa2f7f67624ecb5cc84df7fd21d83dada2e2c75a0_lc_plug_visual_merged_0"/>
                                                    <body name="sfp_module_link" pos="-1.31524e-07 0.0384002 -1.27103e-07" quat="9.11948e-08 -1 -1.41454e-06 -1.27121e-06">
                                                      <inertial pos="0.000140388 0.0140944 0.000755794" quat="0.500874 0.506 -0.492487 0.500546" mass="0.02" diaginertia="3.76251e-06 3.53019e-06 5.94798e-07"/>
                                                      <geom name="port_collider_box" class="world_default" size="0.00071 0.000375 0.0101875" pos="-0.00571 0.022559 -0.00275" quat="0.707107 0.707107 0 0" type="box" group="3"/>
                                                      <geom name="port_collider_box.001" class="world_default" size="0.00125 0.000375 0.0101875" pos="0 0.022559 -0.00275" quat="0.707107 0.707107 0 0" type="box" group="3"/>
                                                      <geom name="port_collider_box.002" class="world_default" size="0.00642 9.5e-05 0.003651" pos="0 0.02732 -0.00447" quat="0.707107 0.707107 0 0" type="box" group="3"/>
                                                      <geom name="port_collider_box.003" class="world_default" size="0.00046 0.0041395 0.0101875" pos="0.00596 0.022559 -8.7e-05" quat="0.707107 0.707107 0 0" type="box" group="3"/>
                                                      <geom name="port_collider_box.004" class="world_default" size="0.00642 0.000674 0.0101875" pos="0 0.022559 0.003049" quat="0.707107 0.707107 0 0" type="box" group="3"/>
                                                      <geom name="port_collider_box.005" class="world_default" size="0.00046 0.0041395 0.0101875" pos="-0.00596 0.022559 -8.7e-05" quat="0.707107 0.707107 0 0" type="box" group="3"/>
                                                      <geom name="port_collider_box.006" class="world_default" size="0.00071 0.000375 0.0101875" pos="0.00571 0.022559 -0.00275" quat="0.707107 0.707107 0 0" type="box" group="3"/>
                                                      <geom name="port_collider_box.007" class="world_default" size="0.00075 0.0038735 0.0101875" pos="0 0.022559 -0.000239" quat="0.707107 0.707107 0 0" type="box" group="3"/>
                                                      <geom name="port_collider_box.008" class="world_default" size="0.00071 0.000503 0.0064415" pos="-0.00571 0.018813 -0.003546" quat="0.707107 0.707107 0 0" type="box" group="3"/>
                                                      <geom name="port_collider_box.009" class="world_default" size="0.00071 0.000503 0.0064415" pos="0.00571 0.018813 -0.003546" quat="0.707107 0.707107 0 0" type="box" group="3"/>
                                                      <geom name="latch_collider_box" class="world_default" size="0.00692 0.0008005 0.001713" pos="0 0.029531 -0.005175" quat="0.707107 0.707107 0 0" type="box" group="3"/>
                                                      <geom name="latch_collider_box.001" class="world_default" size="0.0005145 0.004772 0.00185" pos="0.006405 0.030896 0.000207" quat="0.707107 0.707107 0 0" type="box" group="3"/>
                                                      <geom name="latch_collider_box.002" class="world_default" size="0.00692 0.0011915 0.00185" pos="0 0.030896 0.004716" quat="0.707107 0.707107 0 0" type="box" group="3"/>
                                                      <geom name="latch_collider_box.003" class="world_default" size="0.0004825 0.004772 0.00185" pos="-0.006437 0.030896 0.000207" quat="0.707107 0.707107 0 0" type="box" group="3"/>
                                                      <geom name="head_collider_box" class="world_default" size="0.000642 0.005125 0.0027" pos="0.006358 0.026353 0.000375" quat="0.707107 0.707107 0 0" type="box" group="3"/>
                                                      <geom name="head_collider_box.001" class="world_default" size="0.000642 0.005485 0.0027" pos="-0.006358 0.026353 0.000765" quat="0.707107 0.707107 0 0" type="box" group="3"/>
                                                      <geom name="head_collider_box.002" class="world_default" size="0.007 0.0011225 0.0027" pos="0 0.026353 0.005128" quat="0.707107 0.707107 0 0" type="box" group="3"/>
                                                      <geom name="head_collider_box.003" class="world_default" size="0.007 0.0001875 0.0027" pos="0 0.026353 -0.004563" quat="0.707107 0.707107 0 0" type="box" group="3"/>
                                                      <geom name="body_collider_box" class="world_default" size="0.006875 0.02365 0.0003945" pos="0 0.001 0.00383" type="box" group="3"/>
                                                      <geom name="body_collider_box.001" class="world_default" size="0.006875 0.02365 8.9e-05" pos="0 0.001 -0.004138" type="box" group="3"/>
                                                      <geom name="body_collider_box.002" class="world_default" size="0.000287 0.02365 0.004225" pos="-0.006588 0.001 0" type="box" group="3"/>
                                                      <geom name="body_collider_box.003" class="world_default" size="0.0004055 0.02365 0.004225" pos="0.00647 0.001 0" type="box" group="3"/>
                                                      <geom name="port_collider_box.010" class="world_default" size="0.00642 0.0038815 0.0058645" pos="0 0.01229 0.000119" quat="0.707107 0.707107 0 0" type="box" group="3"/>
                                                      <geom name="port_collider_box002_collider_box" class="world_default" size="0.00642 0.0002045 0.0008005" pos="0 0.024453 -0.004254" quat="0.707107 0.707107 0 0" type="box" group="3"/>
                                                      <geom name="port_collider_box.011" class="world_default" size="0.00125 0.000503 0.0064415" pos="0 0.018813 -0.003546" quat="0.707107 0.707107 0 0" type="box" group="3"/>
                                                      <geom name="sfp_module_visual" class="world_default" type="mesh" contype="0" conaffinity="0" material="material_07ae86fedcbbab3b5759a8a6e79ba15af5075968dd5eac2cb4666913710c9b1a_sfp_module_visual_Body.005" mesh="07ae86fedcbbab3b5759a8a6e79ba15af5075968dd5eac2cb4666913710c9b1a_sfp_module_visual_Body.005"/>
                                                      <geom name="sfp_module_visual_0" class="world_default" type="mesh" contype="0" conaffinity="0" material="material_07ae86fedcbbab3b5759a8a6e79ba15af5075968dd5eac2cb4666913710c9b1a_sfp_module_visual_Body.005_1" mesh="07ae86fedcbbab3b5759a8a6e79ba15af5075968dd5eac2cb4666913710c9b1a_sfp_module_visual_Body.005_1"/>
                                                      <body name="sfp_tip_link" pos="1.07604e-07 -0.02365 -1.00626e-07" quat="0.707105 0.707108 -1.98331e-07 -5.56398e-07">
                                                        <inertial pos="0 0 0" mass="0.001" diaginertia="1e-06 1e-06 1e-06"/>
                                                        <geom name="contact_collision" class="world_default" size="0.006875 0.0021125 0.0005" pos="0 0.0021125 -0.0005" type="box" group="3"/>
                                                        <geom name="non_contact_collision" class="world_default" size="0.006875 0.0021125 0.0005" pos="0 -0.0021125 -0.0005" type="box" group="3"/>
                                                      </body>
                                                    </body>
                                                  </body>
                                                </body>
                                              </body>
                                            </body>
                                          </body>
                                        </body>
                                      </body>
                                    </body>
                                  </body>
                                </body>
                              </body>
                            </body>
                          </body>
                        </body>
                      </body>
                    </body>
                  </body>
                </body>
              </body>
            </body>
          </body>
        </body>
        <body name="sc_plug_link" pos="-0.052 -9.74728e-09 1.05579e-08" quat="1.28973e-06 5.38484e-08 -5.80883e-08 1">
          <inertial pos="-0.00907511 4.9566e-05 8.71699e-06" quat="0.000872542 0.70691 -0.000868656 0.707302" mass="0.04" diaginertia="8.85404e-06 7.17322e-06 2.12253e-06"/>
          <geom name="housing blue_predeterminado005_collider_box" class="world_default" size="0.0063605 0.0045 0.00365" pos="0.002038 0.006344 4e-06" type="box" group="3"/>
          <geom name="housing blue_predeterminado005_collider_box.001" class="world_default" size="0.0063605 0.0045 0.00365" pos="0.002038 -0.006344 4e-06" type="box" group="3"/>
          <geom name="housing blue_predeterminado005_collider_box.002" class="world_default" size="0.006861 0.0035 0.00365" pos="0.002539 0.006344 4e-06" type="box" group="3"/>
          <geom name="housing blue_predeterminado005_collider_box.003" class="world_default" size="0.006861 0.0035 0.00365" pos="0.002539 -0.006344 4e-06" type="box" group="3"/>
          <geom name="housing blue_predeterminado005_collider_box.004" class="world_default" size="0.001 0.000705 0.00365" pos="0.008191 0.003056 4e-06" quat="0.92388 0 0 -0.382683" type="box" group="3"/>
          <geom name="housing blue_predeterminado005_collider_box.005" class="world_default" size="0.001 0.000705 0.00365" pos="0.008191 0.009636 4e-06" quat="0.92388 0 0 0.382683" type="box" group="3"/>
          <geom name="housing blue_predeterminado005_collider_box.006" class="world_default" size="0.001 0.000705 0.00365" pos="0.008191 -0.009636 4e-06" quat="0.92388 0 0 -0.382683" type="box" group="3"/>
          <geom name="housing blue_predeterminado005_collider_box.007" class="world_default" size="0.001 0.000705 0.00365" pos="0.008191 -0.003056 4e-06" quat="0.92388 0 0 0.382683" type="box" group="3"/>
          <geom name="cube002_collider_box" class="world_default" size="0.006275 0.0125 0.00505" pos="-0.010291 0 0" type="box" group="3"/>
          <geom name="cylinder011_collider_cylinder" class="world_default" size="0.0029 0.014605" pos="-0.031147 -0.00635 0" quat="0.707107 0 0.707107 0" type="cylinder" group="3"/>
          <geom name="cylinder005_collider_cylinder" class="world_default" size="0.0029 0.015799" pos="-0.029953 0.00635 0" quat="0.707107 0 0.707107 0" type="cylinder" group="3"/>
          <geom name="ferula_predeterminado005_collider_cylinder" class="world_default" size="0.00125 0.007" pos="0.00465 -0.00635 0" quat="0.707107 0 0.707107 0" type="cylinder" group="3"/>
          <geom name="ferula_predeterminado003_collider_cylinder" class="world_default" size="0.00125 0.007" pos="0.00465 0.00635 0" quat="0.707107 0 0.707107 0" type="cylinder" group="3"/>
          <geom name="side_box_collision" class="world_default" size="0.002125 0.00081 0.0005" pos="0.00146 -0.00632 0.0042" type="box" group="3"/>
          <geom name="side_box_collision_2" class="world_default" size="0.002125 0.00081 0.0005" pos="0.00146 0.00632 0.0042" type="box" group="3"/>
          <geom name="sc_plug_visual" class="world_default" type="mesh" contype="0" conaffinity="0" material="material_39e0c36083c2ebca1948ca6b7f99419210f3b34232289a37761dbe25cefc0443_sc_plug_visual_merged_0" mesh="39e0c36083c2ebca1948ca6b7f99419210f3b34232289a37761dbe25cefc0443_sc_plug_visual_merged_0"/>
          <body name="sc_tip_link" pos="0.01165 -1.79781e-08 -1.5368e-09" quat="0.499998 -0.5 0.500002 -0.5">
            <inertial pos="0 0 0" mass="0.001" diaginertia="1e-06 1e-06 1e-06"/>
          </body>
        </body>
      </body>
    </body>
    <body name="task_board_base_link" pos="0.155471 -0.256823 1.14" quat="0.977569 4.3227e-08 -1.28701e-09 -0.210614">
      <inertial pos="0.00107843 -0.00165069 0.000196078" quat="0.710452 0.643306 0.191518 0.211508" mass="5.1" diaginertia="0.102001 0.102001 0.101"/>
      <geom name="task_board_base_link_fixed_joint_lump__v1015083001_collider_box_left_collision" class="world_default" size="0.15 0.114 0.0045" pos="0 -0.1 0.0075" type="box" group="3"/>
      <geom name="task_board_base_link_fixed_joint_lump__v1015083001_collider_right_collision_1" class="world_default" size="0.15 0.0635 0.0045" pos="0 0.149 0.0075" type="box" group="3"/>
      <geom name="task_board_base_link_fixed_joint_lump__v1015083001_collider_mid_collision_2" class="world_default" size="0.07 0.006 0.0045" pos="-0.075 0.05 0.0075" type="box" group="3"/>
      <geom name="task_board_base_link_fixed_joint_lump__v1015083001_collider_bottom_collision_3" class="world_default" size="0.0825 0.2125 0.0045" pos="0.068 0 0.0075" type="box" group="3"/>
      <geom name="task_board_base_link_fixed_joint_lump__v1015083001_collider_top_collision_4" class="world_default" size="0.0075 0.2125 0.0045" pos="-0.143 0 0.0075" type="box" group="3"/>
      <geom name="task_board_base_link_fixed_joint_lump__iso_4762_m2_x_8072_collider_box_collision_5" class="world_default" size="0.0147285 0.008875 0.0025" pos="0.088272 -0.0841113 0.0124989" quat="0.999891 -0.0147462 0 0" type="box" group="3"/>
      <geom name="task_board_base_link_fixed_joint_lump__iso_4762_m2_x_8072_collider_box_001_collision_6" class="world_default" size="0.0192665 0.008875 0.000864" pos="0.071366 -0.0836795 0.0271365" quat="0.923779 -0.0136237 -0.382642 0.00564313" type="box" group="3"/>
      <geom name="task_board_base_link_fixed_joint_lump__iso_4762_m2_x_8072_collider_box_002_collision_7" class="world_default" size="0.0137425 0.008875 0.001844" pos="0.083636 -0.083811 0.0226785" quat="0.923779 -0.0136237 -0.382642 0.00564313" type="box" group="3"/>
      <geom name="task_board_base_link_fixed_joint_lump__iso_4762_m2_x_8072_collider_box_003_collision_8" class="world_default" size="0.0180555 0.0011525 0.005478" pos="0.076242 -0.0760531 0.0237452" quat="0.923779 -0.0136237 -0.382642 0.00564313" type="box" group="3"/>
      <geom name="task_board_base_link_fixed_joint_lump__iso_4762_m2_x_8072_collider_box_004_collision_9" class="world_default" size="0.0180555 0.0009375 0.005815" pos="0.076003 -0.0917003 0.0244449" quat="0.923779 -0.0136237 -0.382642 0.00564313" type="box" group="3"/>
      <geom name="task_board_base_link_fixed_joint_lump__iso_4762_m2_x_8072_collider_box_005_collision_10" class="world_default" size="0.002532 0.008875 0.005815" pos="0.065017 -0.0840897 0.0132296" quat="0.923779 -0.0136237 -0.382642 0.00564313" type="box" group="3"/>
      <geom name="task_board_base_link_fixed_joint_lump__iso_4762_m2_x_8072_collider_box_006_collision_11" class="world_default" size="0.0071855 0.008875 0.0025" pos="0.0592 -0.0841113 0.0124989" quat="0.999891 -0.0147462 0 0" type="box" group="3"/>
      <geom name="task_board_base_link_fixed_joint_lump__iso_4762_m2_x_8072_collider_box_007_collision_12" class="world_default" size="0.0024465 0.008875 0.0083775" pos="0.091553 -0.0838379 0.0217659" quat="0.999891 -0.0147462 0 0" type="box" group="3"/>
      <geom name="task_board_base_link_fixed_joint_lump__base_visual_visual" class="world_default" type="mesh" contype="0" conaffinity="0" material="material_19f4a95a97b71184a4988be290e52b57fe33862b52d650c82c5d8bc673fc5603_base_visual_ISO_4762_-_M3_x_8.019" mesh="19f4a95a97b71184a4988be290e52b57fe33862b52d650c82c5d8bc673fc5603_base_visual_ISO_4762_-_M3_x_8.019"/>
      <geom name="task_board_base_link_fixed_joint_lump__base_visual_visual_0" class="world_default" type="mesh" contype="0" conaffinity="0" material="material_19f4a95a97b71184a4988be290e52b57fe33862b52d650c82c5d8bc673fc5603_base_visual_ISO_4762_-_M3_x_8.019_1" mesh="19f4a95a97b71184a4988be290e52b57fe33862b52d650c82c5d8bc673fc5603_base_visual_ISO_4762_-_M3_x_8.019_1"/>
      <geom name="task_board_base_link_fixed_joint_lump__base_visual_visual_1" class="world_default" type="mesh" contype="0" conaffinity="0" material="material_19f4a95a97b71184a4988be290e52b57fe33862b52d650c82c5d8bc673fc5603_base_visual_ISO_4762_-_M3_x_8.019_2" mesh="19f4a95a97b71184a4988be290e52b57fe33862b52d650c82c5d8bc673fc5603_base_visual_ISO_4762_-_M3_x_8.019_2"/>
      <geom name="task_board_base_link_fixed_joint_lump__sfp_mount_visual_visual_1" class="world_default" pos="0.055 -0.084185 0.01" quat="0.999891 -0.0147462 0 0" type="mesh" contype="0" conaffinity="0" material="material_0caf49b143bca9a0c9a13d66d2f75335ec2e74c5bba5cfb7bf0c411aed5bc2cd_sfp_mount_visual_ISO_4762_-_M2_x_8.011" mesh="0caf49b143bca9a0c9a13d66d2f75335ec2e74c5bba5cfb7bf0c411aed5bc2cd_sfp_mount_visual_ISO_4762_-_M2_x_8.011"/>
      <geom name="task_board_base_link_fixed_joint_lump__sfp_mount_visual_visual_1_0" class="world_default" pos="0.055 -0.084185 0.01" quat="0.999891 -0.0147462 0 0" type="mesh" contype="0" conaffinity="0" material="material_0caf49b143bca9a0c9a13d66d2f75335ec2e74c5bba5cfb7bf0c411aed5bc2cd_sfp_mount_visual_ISO_4762_-_M2_x_8.011_1" mesh="0caf49b143bca9a0c9a13d66d2f75335ec2e74c5bba5cfb7bf0c411aed5bc2cd_sfp_mount_visual_ISO_4762_-_M2_x_8.011_1"/>
    </body>
    <body name="static_link">
      <inertial pos="0 0 0" mass="1" diaginertia="1 1 1"/>
    </body>
    <body name="static_link_0">
      <inertial pos="0 0 0" mass="1" diaginertia="1 1 1"/>
    </body>
  </worldbody>

  <contact>
    <exclude body1="cable_end_0" body2="link_1"/>
  </contact>

  <equality>
    <weld body1="ati/tool_link" body2="lc_plug_link" relpose="-0.000711 0.001759 0.168213 0.577301 0.816105 -0.021418 -0.015395" solref="0.002 1" solimp="0.99 0.999 0.001"/>
  </equality>
</mujoco>
