<mujoco model="aic_world">
  <compiler angle="radian"/>

  <option gravity="0 0 -9.8" magnetic="5.5645e-06 2.28758e-05 -4.23884e-05"/>

  <visual>
    <headlight ambient="0 0 0" diffuse="0 0 0" specular="0 0 0"/>
  </visual>

  <default>
    <default class="world_default"/>
    <default class="cable_default">
      <joint damping="0.1"/>
    </default>
  </default>

  <extension>
    <plugin plugin="mujoco.elasticity.cable">
      <instance name="composite">
        <config key="twist" value="1e2"/>
        <config key="bend" value="4e1"/>
      </instance>
    </plugin>
  </extension>

  <asset>
    <texture type="2d" colorspace="linear" name="texture_7d2d03d984e0bd4273d245008f309f6a2ab0c0d6961ab1d51b3160a265d7b5a4_floor_visual_Plane" file="7d2d03d984e0bd4273d245008f309f6a2ab0c0d6961ab1d51b3160a265d7b5a4_floor_visual_b3a94635-54d6beff6424435d3828cb4c8a1278d9ea3964b0.png"/>
    <texture type="2d" colorspace="linear" name="texture_39e0c36083c2ebca1948ca6b7f99419210f3b34232289a37761dbe25cefc0443_sc_plug_visual_merged_0" file="39e0c36083c2ebca1948ca6b7f99419210f3b34232289a37761dbe25cefc0443_sc_plug_visual_5875f865-48f62b2f4840d852c7f39a01e6c183037dc1485b.png"/>
    <texture type="2d" colorspace="linear" name="texture_79d083415a0beb7006489abaa2f7f67624ecb5cc84df7fd21d83dada2e2c75a0_lc_plug_visual_merged_0" file="79d083415a0beb7006489abaa2f7f67624ecb5cc84df7fd21d83dada2e2c75a0_lc_plug_visual_03dabf32-0905e8a8aa368516e682f6ec84258100cdb4efef.png"/>
    <texture type="2d" colorspace="linear" name="texture_07ae86fedcbbab3b5759a8a6e79ba15af5075968dd5eac2cb4666913710c9b1a_sfp_module_visual_Body.005" file="07ae86fedcbbab3b5759a8a6e79ba15af5075968dd5eac2cb4666913710c9b1a_sfp_module_visual_8fc63b58-7471eafc55dcb668ae68adfe70a147b363ba3be9.png"/>
    <texture type="2d" colorspace="linear" name="texture_07ae86fedcbbab3b5759a8a6e79ba15af5075968dd5eac2cb4666913710c9b1a_sfp_module_visual_Body.005_1" file="07ae86fedcbbab3b5759a8a6e79ba15af5075968dd5eac2cb4666913710c9b1a_sfp_module_visual_1f09e86a-a4dc4a72bd6e778067310898a5c179607fd78966.png"/>
    <material name="material_21630dbca88254236676b9eaa3d656b1a410544dc4182b3953f5492d6064c1ce_enclosure_visual_V1014952.001" class="world_default" shininess="30" rgba="0.290196 0.290196 0.290196 1"/>
    <material name="material_21630dbca88254236676b9eaa3d656b1a410544dc4182b3953f5492d6064c1ce_enclosure_visual_V1014952.001_1" class="world_default" shininess="30" rgba="0.129412 0.129412 0.133333 1"/>
    <material name="material_21630dbca88254236676b9eaa3d656b1a410544dc4182b3953f5492d6064c1ce_light_visual_Plane.001" class="world_default" shininess="30" rgba="0.5 0.5 0.5 1"/>
    <material name="material_7d2d03d984e0bd4273d245008f309f6a2ab0c0d6961ab1d51b3160a265d7b5a4_floor_visual_Plane" class="world_default" texture="texture_7d2d03d984e0bd4273d245008f309f6a2ab0c0d6961ab1d51b3160a265d7b5a4_floor_visual_Plane" shininess="30" rgba="0.5 0.5 0.5 1"/>
    <material name="material_7d2d03d984e0bd4273d245008f309f6a2ab0c0d6961ab1d51b3160a265d7b5a4_walls_visual_Curve.001" class="world_default" shininess="30" rgba="0.0196078 0.0196078 0.0196078 1"/>
    <material name="material_7d2d03d984e0bd4273d245008f309f6a2ab0c0d6961ab1d51b3160a265d7b5a4_walls_visual_merged_1" class="world_default" shininess="30" rgba="0.262745 0.262745 0.262745 1"/>
    <material name="material_7d2d03d984e0bd4273d245008f309f6a2ab0c0d6961ab1d51b3160a265d7b5a4_walls_visual_Plane.003_1" class="world_default" shininess="30" rgba="0.8 0.8 0.8 1"/>
    <material name="material_7d2d03d984e0bd4273d245008f309f6a2ab0c0d6961ab1d51b3160a265d7b5a4_walls_visual_Plane.002" class="world_default" shininess="30" rgba="0.207843 0.207843 0.207843 1"/>
    <material name="material_19f4a95a97b71184a4988be290e52b57fe33862b52d650c82c5d8bc673fc5603_base_visual_ISO_4762_-_M3_x_8.019" class="world_default" shininess="30" rgba="0.0352941 0.0352941 0.0313726 1"/>
    <material name="material_19f4a95a97b71184a4988be290e52b57fe33862b52d650c82c5d8bc673fc5603_base_visual_ISO_4762_-_M3_x_8.019_1" class="world_default" shininess="30" rgba="0.0313726 0.0313726 0.0313726 1"/>
    <material name="material_19f4a95a97b71184a4988be290e52b57fe33862b52d650c82c5d8bc673fc5603_base_visual_ISO_4762_-_M3_x_8.019_2" class="world_default" shininess="30" rgba="0.215686 0 0.215686 1"/>
    <material name="material_39e0c36083c2ebca1948ca6b7f99419210f3b34232289a37761dbe25cefc0443_sc_plug_visual_merged_0" class="world_default" texture="texture_39e0c36083c2ebca1948ca6b7f99419210f3b34232289a37761dbe25cefc0443_sc_plug_visual_merged_0" shininess="30" rgba="0.5 0.5 0.5 1"/>
    <material name="material_79d083415a0beb7006489abaa2f7f67624ecb5cc84df7fd21d83dada2e2c75a0_lc_plug_visual_merged_0" class="world_default" texture="texture_79d083415a0beb7006489abaa2f7f67624ecb5cc84df7fd21d83dada2e2c75a0_lc_plug_visual_merged_0" shininess="30" rgba="0.5 0.5 0.5 1"/>
    <material name="material_07ae86fedcbbab3b5759a8a6e79ba15af5075968dd5eac2cb4666913710c9b1a_sfp_module_visual_Body.005" class="world_default" texture="texture_07ae86fedcbbab3b5759a8a6e79ba15af5075968dd5eac2cb4666913710c9b1a_sfp_module_visual_Body.005" shininess="30" rgba="0.5 0.5 0.5 1"/>
    <material name="material_07ae86fedcbbab3b5759a8a6e79ba15af5075968dd5eac2cb4666913710c9b1a_sfp_module_visual_Body.005_1" class="world_default" texture="texture_07ae86fedcbbab3b5759a8a6e79ba15af5075968dd5eac2cb4666913710c9b1a_sfp_module_visual_Body.005_1" shininess="30" rgba="0.5 0.5 0.5 1"/>
    <mesh name="21630dbca88254236676b9eaa3d656b1a410544dc4182b3953f5492d6064c1ce_enclosure_visual_V1014952.001" class="world_default" content_type="model/obj" file="21630dbca88254236676b9eaa3d656b1a410544dc4182b3953f5492d6064c1ce_enclosure_visual_V1014952.001-c990efe7b9dfe87aa065fd6eb3960ce051ae2aef.obj" inertia="shell"/>
    <mesh name="21630dbca88254236676b9eaa3d656b1a410544dc4182b3953f5492d6064c1ce_enclosure_visual_V1014952.001_1" class="world_default" content_type="model/obj" file="21630dbca88254236676b9eaa3d656b1a410544dc4182b3953f5492d6064c1ce_enclosure_visual_V1014952.001_1-807e07de06af157c84b994a232617507a7059420.obj" inertia="shell"/>
    <mesh name="21630dbca88254236676b9eaa3d656b1a410544dc4182b3953f5492d6064c1ce_light_visual_Plane.001" class="world_default" content_type="model/obj" file="21630dbca88254236676b9eaa3d656b1a410544dc4182b3953f5492d6064c1ce_light_visual_Plane.001-a8a774a80bc239d73769a498eae528b206eebcb0.obj" inertia="shell"/>
    <mesh name="7d2d03d984e0bd4273d245008f309f6a2ab0c0d6961ab1d51b3160a265d7b5a4_floor_visual_Plane" class="world_default" content_type="model/obj" file="7d2d03d984e0bd4273d245008f309f6a2ab0c0d6961ab1d51b3160a265d7b5a4_floor_visual_Plane-4dc7f6150ad7c239769a0860a01efb2015657aea.obj" inertia="shell"/>
    <mesh name="7d2d03d984e0bd4273d245008f309f6a2ab0c0d6961ab1d51b3160a265d7b5a4_walls_visual_Curve.001" class="world_default" content_type="model/obj" file="7d2d03d984e0bd4273d245008f309f6a2ab0c0d6961ab1d51b3160a265d7b5a4_walls_visual_Curve.001-4d7c79ac2e958832fdb15589262141ca1b80d3a5.obj" inertia="shell"/>
    <mesh name="7d2d03d984e0bd4273d245008f309f6a2ab0c0d6961ab1d51b3160a265d7b5a4_walls_visual_merged_1" class="world_default" content_type="model/obj" file="7d2d03d984e0bd4273d245008f309f6a2ab0c0d6961ab1d51b3160a265d7b5a4_walls_visual_merged_1-359a22140d528747936e80bedf90e1437a177a9f.obj" inertia="shell"/>
    <mesh name="7d2d03d984e0bd4273d245008f309f6a2ab0c0d6961ab1d51b3160a265d7b5a4_walls_visual_Plane.003_1" class="world_default" content_type="model/obj" file="7d2d03d984e0bd4273d245008f309f6a2ab0c0d6961ab1d51b3160a265d7b5a4_walls_visual_Plane.003_1-cd05ed21fa19a2784fb772d7519abf7c31c8b85f.obj" inertia="shell"/>
    <mesh name="7d2d03d984e0bd4273d245008f309f6a2ab0c0d6961ab1d51b3160a265d7b5a4_walls_visual_Plane.002" class="world_default" content_type="model/obj" file="7d2d03d984e0bd4273d245008f309f6a2ab0c0d6961ab1d51b3160a265d7b5a4_walls_visual_Plane.002-ee4f781765eec46c2256d941981732d4b1857f24.obj" inertia="shell"/>
    <mesh name="19f4a95a97b71184a4988be290e52b57fe33862b52d650c82c5d8bc673fc5603_base_visual_ISO_4762_-_M3_x_8.019" class="world_default" content_type="model/obj" file="19f4a95a97b71184a4988be290e52b57fe33862b52d650c82c5d8bc673fc5603_base_visual_ISO_4762_-_M3_x_8.019-f814bb518c42769543ab6246809f3fe4af5c2b64.obj" inertia="shell"/>
    <mesh name="19f4a95a97b71184a4988be290e52b57fe33862b52d650c82c5d8bc673fc5603_base_visual_ISO_4762_-_M3_x_8.019_1" class="world_default" content_type="model/obj" file="19f4a95a97b71184a4988be290e52b57fe33862b52d650c82c5d8bc673fc5603_base_visual_ISO_4762_-_M3_x_8.019_1-0b276ba9910a7642121235b62d2afc47c3995782.obj" inertia="shell"/>
    <mesh name="19f4a95a97b71184a4988be290e52b57fe33862b52d650c82c5d8bc673fc5603_base_visual_ISO_4762_-_M3_x_8.019_2" class="world_default" content_type="model/obj" file="19f4a95a97b71184a4988be290e52b57fe33862b52d650c82c5d8bc673fc5603_base_visual_ISO_4762_-_M3_x_8.019_2-7b96569be9572803417c5650ee83c9c883b44191.obj" inertia="shell"/>
    <mesh name="39e0c36083c2ebca1948ca6b7f99419210f3b34232289a37761dbe25cefc0443_sc_plug_visual_merged_0" class="world_default" content_type="model/obj" file="39e0c36083c2ebca1948ca6b7f99419210f3b34232289a37761dbe25cefc0443_sc_plug_visual_merged_0-67f94accf247f722dd4954d7448d7956402901f2.obj" inertia="shell"/>
    <mesh name="79d083415a0beb7006489abaa2f7f67624ecb5cc84df7fd21d83dada2e2c75a0_lc_plug_visual_merged_0" class="world_default" content_type="model/obj" file="79d083415a0beb7006489abaa2f7f67624ecb5cc84df7fd21d83dada2e2c75a0_lc_plug_visual_merged_0-fdaf59710fc3cc118a7df05add4ff4205edda4ef.obj" inertia="shell"/>
    <mesh name="07ae86fedcbbab3b5759a8a6e79ba15af5075968dd5eac2cb4666913710c9b1a_sfp_module_visual_Body.005" class="world_default" content_type="model/obj" file="07ae86fedcbbab3b5759a8a6e79ba15af5075968dd5eac2cb4666913710c9b1a_sfp_module_visual_Body.005-f93147e1e403de321fb70c06a4b1e00f20feb9fd.obj" inertia="shell"/>
    <mesh name="07ae86fedcbbab3b5759a8a6e79ba15af5075968dd5eac2cb4666913710c9b1a_sfp_module_visual_Body.005_1" class="world_default" content_type="model/obj" file="07ae86fedcbbab3b5759a8a6e79ba15af5075968dd5eac2cb4666913710c9b1a_sfp_module_visual_Body.005_1-4af964a95522e2593eb6381eca4f09ef239782c7.obj" inertia="shell"/>
  </asset>

  <worldbody>
    <light name="enclosure_light" class="world_default" pos="0 0 2.5" dir="0 0 -1" intensity="0.4" range="2" attenuation="1 0.01 0.001" cutoff="114.592" exponent="0.993023" diffuse="1 1 1" specular="0.1 0.1 0.1"/>
    <light name="ceiling_01" class="world_default" pos="2 2 6" dir="0 0 -1" intensity="2" range="9" castshadow="false" attenuation="1 0.01 0.001" cutoff="360" diffuse="1 1 1" specular="0.1 0.1 0.1"/>
    <light name="ceiling_02" class="world_default" pos="-2 -2 6" dir="0 0 -1" intensity="2" range="9" castshadow="false" attenuation="1 0.01 0.001" cutoff="360" diffuse="1 1 1" specular="0.1 0.1 0.1"/>
    <body name="enclosure_link">
      <inertial pos="0 0 0" mass="1" diaginertia="1 1 1"/>
      <geom name="v1015026001_collider_box" class="world_default" size="0.75 0.569492 0.75" pos="-0.010998 0.009283 0.569706" quat="-1.22475e-07 1.22474e-07 -0.707107 -0.707107" type="box" group="3"/>
      <geom name="v1015028001_collider_box" class="world_default" size="0.0254 0.0254 1.25" pos="0.713602 0.733883 1.3292" quat="1.73205e-07 0 0 -1" type="box" group="3"/>
      <geom name="v1015013001_collider_box" class="world_default" size="0.0304 0.75 0.75" pos="-0.010998 0.009283 2.5488" quat="0.707107 0 -0.707107 0" type="box" group="3"/>
      <geom name="v1015027_collider_box" class="world_default" size="0.0254 0.0254 1.25" pos="-0.735598 0.733883 1.3292" quat="1.73205e-07 0 0 -1" type="box" group="3"/>
      <geom name="v1015029_collider_box" class="world_default" size="0.0254 0.0254 1.25" pos="-0.735598 -0.715317 1.3292" quat="0 1.73205e-07 -1 -1.73205e-07" type="box" group="3"/>
      <geom name="v1015030_collider_box" class="world_default" size="0.0254 0.0254 1.25" pos="0.713602 -0.715317 1.3292" quat="1.73205e-07 0 0 -1" type="box" group="3"/>
      <geom name="enclosure_visual" class="world_default" type="mesh" contype="0" conaffinity="0" material="material_21630dbca88254236676b9eaa3d656b1a410544dc4182b3953f5492d6064c1ce_enclosure_visual_V1014952.001" mesh="21630dbca88254236676b9eaa3d656b1a410544dc4182b3953f5492d6064c1ce_enclosure_visual_V1014952.001"/>
      <geom name="enclosure_visual_0" class="world_default" type="mesh" contype="0" conaffinity="0" material="material_21630dbca88254236676b9eaa3d656b1a410544dc4182b3953f5492d6064c1ce_enclosure_visual_V1014952.001_1" mesh="21630dbca88254236676b9eaa3d656b1a410544dc4182b3953f5492d6064c1ce_enclosure_visual_V1014952.001_1"/>
      <geom name="light_visual" class="world_default" type="mesh" contype="0" conaffinity="0" material="material_21630dbca88254236676b9eaa3d656b1a410544dc4182b3953f5492d6064c1ce_light_visual_Plane.001" mesh="21630dbca88254236676b9eaa3d656b1a410544dc4182b3953f5492d6064c1ce_light_visual_Plane.001"/>
    </body>
    <body name="enclosure_walls_link">
      <inertial pos="0 0 0" mass="1" diaginertia="1 1 1"/>
      <geom name="v1015062006_collider_box" class="world_default" size="0.0250005 0.6796 0.6892" pos="-0.010998 0.734284 1.8288" quat="0.5 0.5 -0.5 -0.5" type="box" group="3"/>
      <geom name="v1015062005_collider_box" class="world_default" size="0.6892 0.6796 0.025" pos="-0.735998 0.009283 1.8288" quat="0.5 0.5 -0.5 -0.5" type="box" group="3"/>
      <geom name="v1015062007_collider_box" class="world_default" size="0.025 0.6846 0.6892" pos="-0.010998 -0.715717 1.8338" quat="0.5 0.5 -0.5 -0.5" type="box" group="3"/>
      <geom name="v1015062008_collider_box" class="world_default" size="0.6892 0.6846 0.025" pos="0.714002 0.009283 1.8338" quat="0.5 0.5 -0.5 -0.5" type="box" group="3"/>
    </body>
    <body name="floor_link">
      <inertial pos="0 0 0" mass="1" diaginertia="1 1 1"/>
      <geom name="floor_cylinder" class="world_default" size="5 5 1" type="plane" group="3"/>
      <geom name="floor_visual" class="world_default" type="mesh" contype="0" conaffinity="0" material="material_7d2d03d984e0bd4273d245008f309f6a2ab0c0d6961ab1d51b3160a265d7b5a4_floor_visual_Plane" mesh="7d2d03d984e0bd4273d245008f309f6a2ab0c0d6961ab1d51b3160a265d7b5a4_floor_visual_Plane"/>
      <geom name="walls_visual" class="world_default" type="mesh" contype="0" conaffinity="0" material="material_7d2d03d984e0bd4273d245008f309f6a2ab0c0d6961ab1d51b3160a265d7b5a4_walls_visual_Curve.001" mesh="7d2d03d984e0bd4273d245008f309f6a2ab0c0d6961ab1d51b3160a265d7b5a4_walls_visual_Curve.001"/>
      <geom name="walls_visual_0" class="world_default" type="mesh" contype="0" conaffinity="0" material="material_7d2d03d984e0bd4273d245008f309f6a2ab0c0d6961ab1d51b3160a265d7b5a4_walls_visual_merged_1" mesh="7d2d03d984e0bd4273d245008f309f6a2ab0c0d6961ab1d51b3160a265d7b5a4_walls_visual_merged_1"/>
      <geom name="walls_visual_1" class="world_default" type="mesh" contype="0" conaffinity="0" material="material_7d2d03d984e0bd4273d245008f309f6a2ab0c0d6961ab1d51b3160a265d7b5a4_walls_visual_Plane.003_1" mesh="7d2d03d984e0bd4273d245008f309f6a2ab0c0d6961ab1d51b3160a265d7b5a4_walls_visual_Plane.003_1"/>
      <geom name="walls_visual_2" class="world_default" type="mesh" contype="0" conaffinity="0" material="material_7d2d03d984e0bd4273d245008f309f6a2ab0c0d6961ab1d51b3160a265d7b5a4_walls_visual_Plane.002" mesh="7d2d03d984e0bd4273d245008f309f6a2ab0c0d6961ab1d51b3160a265d7b5a4_walls_visual_Plane.002"/>
    </body>
    <body name="task_board_base_link" pos="0.15 -0.2 1.14" quat="4.63268e-05 0 0 1">
      <inertial pos="0 0 0" mass="5" diaginertia="0.1 0.1 0.1"/>
      <geom name="task_board_base_link_fixed_joint_lump__v1015083001_collider_box_left_collision" class="world_default" size="0.15 0.114 0.0045" pos="0 -0.1 0.0075" type="box" group="3"/>
      <geom name="task_board_base_link_fixed_joint_lump__v1015083001_collider_right_collision_1" class="world_default" size="0.15 0.0635 0.0045" pos="0 0.149 0.0075" type="box" group="3"/>
      <geom name="task_board_base_link_fixed_joint_lump__v1015083001_collider_mid_collision_2" class="world_default" size="0.07 0.006 0.0045" pos="-0.075 0.05 0.0075" type="box" group="3"/>
      <geom name="task_board_base_link_fixed_joint_lump__v1015083001_collider_bottom_collision_3" class="world_default" size="0.0825 0.2125 0.0045" pos="0.068 0 0.0075" type="box" group="3"/>
      <geom name="task_board_base_link_fixed_joint_lump__v1015083001_collider_top_collision_4" class="world_default" size="0.0075 0.2125 0.0045" pos="-0.143 0 0.0075" type="box" group="3"/>
      <geom name="task_board_base_link_fixed_joint_lump__base_visual_visual" class="world_default" type="mesh" contype="0" conaffinity="0" material="material_19f4a95a97b71184a4988be290e52b57fe33862b52d650c82c5d8bc673fc5603_base_visual_ISO_4762_-_M3_x_8.019" mesh="19f4a95a97b71184a4988be290e52b57fe33862b52d650c82c5d8bc673fc5603_base_visual_ISO_4762_-_M3_x_8.019"/>
      <geom name="task_board_base_link_fixed_joint_lump__base_visual_visual_0" class="world_default" type="mesh" contype="0" conaffinity="0" material="material_19f4a95a97b71184a4988be290e52b57fe33862b52d650c82c5d8bc673fc5603_base_visual_ISO_4762_-_M3_x_8.019_1" mesh="19f4a95a97b71184a4988be290e52b57fe33862b52d650c82c5d8bc673fc5603_base_visual_ISO_4762_-_M3_x_8.019_1"/>
      <geom name="task_board_base_link_fixed_joint_lump__base_visual_visual_1" class="world_default" type="mesh" contype="0" conaffinity="0" material="material_19f4a95a97b71184a4988be290e52b57fe33862b52d650c82c5d8bc673fc5603_base_visual_ISO_4762_-_M3_x_8.019_2" mesh="19f4a95a97b71184a4988be290e52b57fe33862b52d650c82c5d8bc673fc5603_base_visual_ISO_4762_-_M3_x_8.019_2"/>
    </body>
    <body name="cable_end_0" childclass="cable_default" pos="0.171400 0.020606 1.511889" quat="0.712741 0.312130 -0.052173 0.625982">
      <freejoint name="cable_end_0_free"/>
      <inertial pos="0 0 0" mass="0.0025" diaginertia="1e-6 1e-6 1e-6"/>
      <geom name="base_vis" class="world_default" size="0.002" contype="0" conaffinity="0"/>
      <plugin instance="composite"/>
      <body name="cable_connection_0" pos="8.11171e-09 4.6124e-08 -1.60409e-07" quat="0.925311 -0.0906414 -0.3288 0.165752">
        <inertial pos="0 0 0" mass="0.01" diaginertia="1e-6 1e-6 1e-6"/>
        <joint name="joint_connection_end_0" class="world_default" pos="0 0 0" type="ball" damping="0.2"/>
        <geom name="visual_0_0" class="world_default" size="0.001 0.00180278" pos="-0.00180278 0.002 0" quat="0.676768 0.204909 0.676764 -0.204908" type="cylinder" contype="0" conaffinity="0"/>
        <geom name="visual_1_0" class="world_default" size="0.001 0.00180278" pos="-0.00180278 -0.002 0" quat="0.676768 -0.204909 0.676764 0.204908" type="cylinder" contype="0" conaffinity="0"/>
        <plugin instance="composite"/>
        <body name="link_1" pos="0.00199589 -0.00566387 -0.0232367" quat="-0.0719662 -0.263121 -0.956484 0.103568">
          <inertial pos="0 0 0" mass="0.0025" diaginertia="1e-6 1e-6 1e-6"/>
          <joint name="joint_end_0" pos="0 0 -0.024" type="ball"/>
          <geom name="link_1_collision" size="0.002 0.018" pos="0 0 0.006" type="cylinder" group="3"/>
          <geom name="sphere_1_collision" size="0.002" pos="0 0 0.024" group="3"/>
          <geom name="link_1_vis" size="0.002 0.024" type="cylinder" contype="0" conaffinity="0"/>
          <geom name="sphere_1_vis" size="0.002" pos="0 0 0.024" contype="0" conaffinity="0"/>
          <plugin instance="composite"/>
          <body name="link_2" pos="0.00583969 -0.00751812 0.0460317" quat="0.979029 0.157095 0.127808 -0.0221094">
            <inertial pos="0 0 0" mass="0.0025" diaginertia="1e-6 1e-6 1e-6"/>
            <joint name="joint_1" pos="0 0 -0.024" type="ball"/>
            <geom name="link_2_collision" size="0.002 0.024" type="cylinder" group="3"/>
            <geom name="sphere_2_collision" size="0.002" pos="0 0 0.024" group="3"/>
            <geom name="link_2_vis" size="0.002 0.024" type="cylinder" contype="0" conaffinity="0"/>
            <geom name="sphere_2_vis" size="0.002" pos="0 0 0.024" contype="0" conaffinity="0"/>
            <plugin instance="composite"/>
            <body name="link_3" pos="0.000229401 -0.00663957 0.0470625" quat="0.989952 0.139556 0.00783327 -0.0213961">
              <inertial pos="0 0 0" mass="0.0025" diaginertia="1e-6 1e-6 1e-6"/>
              <joint name="joint_2" pos="0 0 -0.024" type="ball"/>
              <geom name="link_3_collision" size="0.002 0.024" type="cylinder" group="3"/>
              <geom name="sphere_3_collision" size="0.002" pos="0 0 0.024" group="3"/>
              <geom name="link_3_vis" size="0.002 0.024" type="cylinder" contype="0" conaffinity="0"/>
              <geom name="sphere_3_vis" size="0.002" pos="0 0 0.024" contype="0" conaffinity="0"/>
              <plugin instance="composite"/>
              <body name="link_4" pos="-0.00226548 -0.00466813 0.0474325" quat="0.993764 0.0989803 -0.0450435 -0.024622">
                <inertial pos="0 0 0" mass="0.0025" diaginertia="1e-6 1e-6 1e-6"/>
                <joint name="joint_3" pos="0 0 -0.024" type="ball"/>
                <geom name="link_4_collision" size="0.002 0.024" type="cylinder" group="3"/>
                <geom name="sphere_4_collision" size="0.002" pos="0 0 0.024" group="3"/>
                <geom name="link_4_vis" size="0.002 0.024" type="cylinder" contype="0" conaffinity="0"/>
                <geom name="sphere_4_vis" size="0.002" pos="0 0 0.024" contype="0" conaffinity="0"/>
                <plugin instance="composite"/>
                <body name="link_5" pos="-0.00370372 -0.00314794 0.0475032" quat="0.993985 0.0690195 -0.0748214 -0.0403857">
                  <inertial pos="0 0 0" mass="0.0025" diaginertia="1e-6 1e-6 1e-6"/>
                  <joint name="joint_4" pos="0 0 -0.024" type="ball"/>
                  <geom name="link_5_collision" size="0.002 0.024" type="cylinder" group="3"/>
                  <geom name="sphere_5_collision" size="0.002" pos="0 0 0.024" group="3"/>
                  <geom name="link_5_vis" size="0.002 0.024" type="cylinder" contype="0" conaffinity="0"/>
                  <geom name="sphere_5_vis" size="0.002" pos="0 0 0.024" contype="0" conaffinity="0"/>
                  <plugin instance="composite"/>
                  <body name="link_6" pos="-0.00400311 -0.00179905 0.0475955" quat="0.993729 0.0429329 -0.0811865 -0.0637859">
                    <inertial pos="0 0 0" mass="0.0025" diaginertia="1e-6 1e-6 1e-6"/>
                    <joint name="joint_5" pos="0 0 -0.024" type="ball"/>
                    <geom name="link_6_collision" size="0.002 0.024" type="cylinder" group="3"/>
                    <geom name="sphere_6_collision" size="0.002" pos="0 0 0.024" group="3"/>
                    <geom name="link_6_vis" size="0.002 0.024" type="cylinder" contype="0" conaffinity="0"/>
                    <geom name="sphere_6_vis" size="0.002" pos="0 0 0.024" contype="0" conaffinity="0"/>
                    <plugin instance="composite"/>
                    <body name="link_7" pos="-0.00350974 -0.00070828 0.047732" quat="0.993366 0.021159 -0.07175 -0.087345">
                      <inertial pos="0 0 0" mass="0.0025" diaginertia="1e-6 1e-6 1e-6"/>
                      <joint name="joint_6" pos="0 0 -0.024" type="ball"/>
                      <geom name="link_7_collision" size="0.002 0.024" type="cylinder" group="3"/>
                      <geom name="sphere_7_collision" size="0.002" pos="0 0 0.024" group="3"/>
                      <geom name="link_7_vis" size="0.002 0.024" type="cylinder" contype="0" conaffinity="0"/>
                      <geom name="sphere_7_vis" size="0.002" pos="0 0 0.024" contype="0" conaffinity="0"/>
                      <plugin instance="composite"/>
                      <body name="link_8" pos="-0.00241006 0.000201061 0.0478785" quat="0.993429 0.000992599 -0.0504423 -0.102728">
                        <inertial pos="0 0 0" mass="0.0025" diaginertia="1e-6 1e-6 1e-6"/>
                        <joint name="joint_7" pos="0 0 -0.024" type="ball"/>
                        <geom name="link_8_collision" size="0.002 0.024" type="cylinder" group="3"/>
                        <geom name="sphere_8_collision" size="0.002" pos="0 0 0.024" group="3"/>
                        <geom name="link_8_vis" size="0.002 0.024" type="cylinder" contype="0" conaffinity="0"/>
                        <geom name="sphere_8_vis" size="0.002" pos="0 0 0.024" contype="0" conaffinity="0"/>
                        <plugin instance="composite"/>
                        <body name="link_9" pos="-0.00116908 0.00100386 0.0479516" quat="0.993967 -0.0182554 -0.0264281 -0.104869">
                          <inertial pos="0 0 0" mass="0.0025" diaginertia="1e-6 1e-6 1e-6"/>
                          <joint name="joint_8" pos="0 0 -0.024" type="ball"/>
                          <geom name="link_9_collision" size="0.002 0.024" type="cylinder" group="3"/>
                          <geom name="sphere_9_collision" size="0.002" pos="0 0 0.024" group="3"/>
                          <geom name="link_9_vis" size="0.002 0.024" type="cylinder" contype="0" conaffinity="0"/>
                          <geom name="sphere_9_vis" size="0.002" pos="0 0 0.024" contype="0" conaffinity="0"/>
                          <plugin instance="composite"/>
                          <body name="link_10" pos="-0.000281844 0.00176533 0.0479336" quat="0.994694 -0.0360494 -0.0093873 -0.0958942">
                            <inertial pos="0 0 0" mass="0.0025" diaginertia="1e-6 1e-6 1e-6"/>
                            <joint name="joint_9" pos="0 0 -0.024" type="ball"/>
                            <geom name="link_10_collision" size="0.002 0.024" type="cylinder" group="3"/>
                            <geom name="sphere_10_collision" size="0.002" pos="0 0 0.024" group="3"/>
                            <geom name="link_10_vis" size="0.002 0.024" type="cylinder" contype="0" conaffinity="0"/>
                            <geom name="sphere_10_vis" size="0.002" pos="0 0 0.024" contype="0" conaffinity="0"/>
                            <plugin instance="composite"/>
                            <body name="link_11" pos="0.00127217 0.00268118 0.0478168" quat="0.993832 -0.0581759 0.0212724 -0.0919863">
                              <inertial pos="0 0 0" mass="0.0025" diaginertia="1e-6 1e-6 1e-6"/>
                              <joint name="joint_10" pos="0 0 -0.024" type="ball"/>
                              <geom name="link_11_collision" size="0.002 0.024" type="cylinder" group="3"/>
                              <geom name="sphere_11_collision" size="0.002" pos="0 0 0.024" group="3"/>
                              <geom name="link_11_vis" size="0.002 0.024" type="cylinder" contype="0" conaffinity="0"/>
                              <geom name="sphere_11_vis" size="0.002" pos="0 0 0.024" contype="0" conaffinity="0"/>
                              <plugin instance="composite"/>
                              <body name="link_12" pos="0.00326411 0.00422113 0.047401" quat="0.991346 -0.0930153 0.0621461 -0.0686962">
                                <inertial pos="0 0 0" mass="0.0025" diaginertia="1e-6 1e-6 1e-6"/>
                                <joint name="joint_11" pos="0 0 -0.024" type="ball"/>
                                <geom name="link_12_collision" size="0.002 0.024" type="cylinder" group="3"/>
                                <geom name="sphere_12_collision" size="0.002" pos="0 0 0.024" group="3"/>
                                <geom name="link_12_vis" size="0.002 0.024" type="cylinder" contype="0" conaffinity="0"/>
                                <geom name="sphere_12_vis" size="0.002" pos="0 0 0.024" contype="0" conaffinity="0"/>
                                <plugin instance="composite"/>
                                <body name="link_13" pos="0.00481414 0.00598266 0.046739" quat="0.985884 -0.130501 0.0961672 -0.0418794">
                                  <inertial pos="0 0 0" mass="0.0025" diaginertia="1e-6 1e-6 1e-6"/>
                                  <joint name="joint_12" pos="0 0 -0.024" type="ball"/>
                                  <geom name="link_13_collision" size="0.002 0.024" type="cylinder" group="3"/>
                                  <geom name="sphere_13_collision" size="0.002" pos="0 0 0.024" group="3"/>
                                  <geom name="link_13_vis" size="0.002 0.024" type="cylinder" contype="0" conaffinity="0"/>
                                  <geom name="sphere_13_vis" size="0.002" pos="0 0 0.024" contype="0" conaffinity="0"/>
                                  <plugin instance="composite"/>
                                  <body name="link_14" pos="0.00590557 0.00750524 0.046019" quat="0.979015 -0.161664 0.123097 -0.0155636">
                                    <inertial pos="0 0 0" mass="0.0025" diaginertia="1e-6 1e-6 1e-6"/>
                                    <joint name="joint_13" pos="0 0 -0.024" type="ball"/>
                                    <geom name="link_14_collision" size="0.002 0.024" type="cylinder" group="3"/>
                                    <geom name="sphere_14_collision" size="0.002" pos="0 0 0.024" group="3"/>
                                    <geom name="link_14_vis" size="0.002 0.024" type="cylinder" contype="0" conaffinity="0"/>
                                    <geom name="sphere_14_vis" size="0.002" pos="0 0 0.024" contype="0" conaffinity="0"/>
                                    <plugin instance="composite"/>
                                    <body name="link_15" pos="0.00663847 0.00818614 0.0455628" quat="0.974244 -0.173866 0.143369 0.00801543">
                                      <inertial pos="0 0 0" mass="0.0025" diaginertia="1e-6 1e-6 1e-6"/>
                                      <joint name="joint_14" pos="0 0 -0.024" type="ball"/>
                                      <geom name="link_15_collision" size="0.002 0.024" type="cylinder" group="3"/>
                                      <geom name="sphere_15_collision" size="0.002" pos="0 0 0.024" group="3"/>
                                      <geom name="link_15_vis" size="0.002 0.024" type="cylinder" contype="0" conaffinity="0"/>
                                      <geom name="sphere_15_vis" size="0.002" pos="0 0 0.024" contype="0" conaffinity="0"/>
                                      <plugin instance="composite"/>
                                      <body name="link_16" pos="0.00692151 0.00767853 0.0456609" quat="0.974948 -0.159916 0.15228 0.0267213">
                                        <inertial pos="0 0 0" mass="0.0025" diaginertia="1e-6 1e-6 1e-6"/>
                                        <joint name="joint_15" pos="0 0 -0.024" type="ball"/>
                                        <geom name="link_16_collision" size="0.002 0.024" type="cylinder" group="3"/>
                                        <geom name="sphere_16_collision" size="0.002" pos="0 0 0.024" group="3"/>
                                        <geom name="link_16_vis" size="0.002 0.024" type="cylinder" contype="0" conaffinity="0"/>
                                        <geom name="sphere_16_vis" size="0.002" pos="0 0 0.024" contype="0" conaffinity="0"/>
                                        <plugin instance="composite"/>
                                        <body name="link_17" pos="0.0068156 0.00605109 0.0462039" quat="0.980324 -0.122627 0.149697 0.0389603">
                                          <inertial pos="0 0 0" mass="0.0025" diaginertia="1e-6 1e-6 1e-6"/>
                                          <joint name="joint_16" pos="0 0 -0.024" type="ball"/>
                                          <geom name="link_17_collision" size="0.002 0.024" type="cylinder" group="3"/>
                                          <geom name="sphere_17_collision" size="0.002" pos="0 0 0.024" group="3"/>
                                          <geom name="link_17_vis" size="0.002 0.024" type="cylinder" contype="0" conaffinity="0"/>
                                          <geom name="sphere_17_vis" size="0.002" pos="0 0 0.024" contype="0" conaffinity="0"/>
                                          <plugin instance="composite"/>
                                          <body name="link_18" pos="0.00641579 0.00357568 0.0468486" quat="0.986989 -0.069395 0.138462 0.0431804">
                                            <inertial pos="0 0 0" mass="0.0025" diaginertia="1e-6 1e-6 1e-6"/>
                                            <joint name="joint_17" pos="0 0 -0.024" type="ball"/>
                                            <geom name="link_18_collision" size="0.002 0.024" type="cylinder" group="3"/>
                                            <geom name="sphere_18_collision" size="0.002" pos="0 0 0.024" group="3"/>
                                            <geom name="link_18_vis" size="0.002 0.024" type="cylinder" contype="0" conaffinity="0"/>
                                            <geom name="sphere_18_vis" size="0.002" pos="0 0 0.024" contype="0" conaffinity="0"/>
                                            <plugin instance="composite"/>
                                            <body name="link_19" pos="0.00637452 0.001384 0.0470976" quat="0.989822 -0.0239813 0.135084 0.0378163">
                                              <inertial pos="0 0 0" mass="0.0025" diaginertia="1e-6 1e-6 1e-6"/>
                                              <joint name="joint_18" pos="0 0 -0.024" type="ball"/>
                                              <geom name="link_19_collision" size="0.002 0.024" type="cylinder" group="3"/>
                                              <geom name="sphere_19_collision" size="0.002" pos="0 0 0.024" group="3"/>
                                              <geom name="link_19_vis" size="0.002 0.024" type="cylinder" contype="0" conaffinity="0"/>
                                              <geom name="sphere_19_vis" size="0.002" pos="0 0 0.024" contype="0" conaffinity="0"/>
                                              <plugin instance="composite"/>
                                              <body name="link_20" pos="0.00586503 -0.00106203 0.0472504" quat="0.991753 0.025731 0.122476 0.0276374">
                                                <inertial pos="0 0 0" mass="0.0025" diaginertia="1e-6 1e-6 1e-6"/>
                                                <joint name="joint_19" pos="0 0 -0.024" type="ball"/>
                                                <geom name="link_20_collision" size="0.002 0.024" type="cylinder" group="3"/>
                                                <geom name="sphere_20_collision" size="0.002" pos="0 0 0.024" group="3"/>
                                                <geom name="link_20_vis" size="0.002 0.024" type="cylinder" contype="0" conaffinity="0"/>
                                                <geom name="sphere_20_vis" size="0.002" pos="0 0 0.024" contype="0" conaffinity="0"/>
                                                <plugin instance="composite"/>
                                                <body name="cable_connection_1" pos="1.04276e-06 -5.58776e-07 0.024" quat="0.776261 0.0592909 -0.626331 -0.0401545">
                                                  <inertial pos="0 0 0" mass="0.01" diaginertia="4e-4 4e-4 4e-4"/>
                                                  <joint name="joint_connection_end_1" class="world_default" pos="0 0 0" type="ball"/>
                                                  <geom name="collision_0" class="world_default" size="0.001 0.00367636" pos="0.00367636 -0.00425 0" quat="0.673802 0.214463 0.673798 -0.214461" type="cylinder" group="3"/>
                                                  <geom name="collision_1" class="world_default" size="0.001 0.00367636" pos="0.00367636 0.00425 0" quat="0.673802 -0.214463 0.673798 0.214461" type="cylinder" group="3"/>
                                                  <geom name="visual_0" class="world_default" size="0.001 0.00367636" pos="0.00367636 -0.00425 0" quat="0.673802 0.214463 0.673798 -0.214461" type="cylinder" contype="0" conaffinity="0"/>
                                                  <geom name="visual_1" class="world_default" size="0.001 0.00367636" pos="0.00367636 0.00425 0" quat="0.673802 -0.214463 0.673798 0.214461" type="cylinder" contype="0" conaffinity="0"/>
                                                  <plugin instance="composite"/>
                                                  <body name="sc_plug_link" pos="0.0520001 2.02247e-07 -5.42255e-08" quat="1 -1.47595e-07 -1.52871e-08 6.15739e-08">
                                                    <inertial pos="-0.00907511 4.9566e-05 8.71699e-06" quat="0.000872542 0.70691 -0.000868656 0.707302" mass="0.04" diaginertia="8.85404e-06 7.17322e-06 2.12253e-06"/>
                                                    <geom name="housing blue_predeterminado005_collider_box" class="world_default" size="0.0063605 0.0045 0.00365" pos="0.002038 0.006344 4e-06" type="box" group="3"/>
                                                    <geom name="housing blue_predeterminado005_collider_box.001" class="world_default" size="0.0063605 0.0045 0.00365" pos="0.002038 -0.006344 4e-06" type="box" group="3"/>
                                                    <geom name="housing blue_predeterminado005_collider_box.002" class="world_default" size="0.006861 0.0035 0.00365" pos="0.002539 0.006344 4e-06" type="box" group="3"/>
                                                    <geom name="housing blue_predeterminado005_collider_box.003" class="world_default" size="0.006861 0.0035 0.00365" pos="0.002539 -0.006344 4e-06" type="box" group="3"/>
                                                    <geom name="housing blue_predeterminado005_collider_box.004" class="world_default" size="0.001 0.000705 0.00365" pos="0.008191 0.003056 4e-06" quat="0.92388 0 0 -0.382683" type="box" group="3"/>
                                                    <geom name="housing blue_predeterminado005_collider_box.005" class="world_default" size="0.001 0.000705 0.00365" pos="0.008191 0.009636 4e-06" quat="0.92388 0 0 0.382683" type="box" group="3"/>
                                                    <geom name="housing blue_predeterminado005_collider_box.006" class="world_default" size="0.001 0.000705 0.00365" pos="0.008191 -0.009636 4e-06" quat="0.92388 0 0 -0.382683" type="box" group="3"/>
                                                    <geom name="housing blue_predeterminado005_collider_box.007" class="world_default" size="0.001 0.000705 0.00365" pos="0.008191 -0.003056 4e-06" quat="0.92388 0 0 0.382683" type="box" group="3"/>
                                                    <geom name="cube002_collider_box" class="world_default" size="0.006275 0.0125 0.00505" pos="-0.010291 0 0" type="box" group="3"/>
                                                    <geom name="cylinder011_collider_cylinder" class="world_default" size="0.0029 0.014605" pos="-0.031147 -0.00635 0" quat="0.707107 0 0.707107 0" type="cylinder" group="3"/>
                                                    <geom name="cylinder005_collider_cylinder" class="world_default" size="0.0029 0.015799" pos="-0.029953 0.00635 0" quat="0.707107 0 0.707107 0" type="cylinder" group="3"/>
                                                    <geom name="ferula_predeterminado005_collider_cylinder" class="world_default" size="0.00125 0.007" pos="0.00465 -0.00635 0" quat="0.707107 0 0.707107 0" type="cylinder" group="3"/>
                                                    <geom name="ferula_predeterminado003_collider_cylinder" class="world_default" size="0.00125 0.007" pos="0.00465 0.00635 0" quat="0.707107 0 0.707107 0" type="cylinder" group="3"/>
                                                    <geom name="side_box_collision" class="world_default" size="0.002125 0.00081 0.0005" pos="0.00146 -0.00632 0.0042" type="box" group="3"/>
                                                    <geom name="side_box_collision_2" class="world_default" size="0.002125 0.00081 0.0005" pos="0.00146 0.00632 0.0042" type="box" group="3"/>
                                                    <geom name="sc_plug_visual" class="world_default" type="mesh" contype="0" conaffinity="0" material="material_39e0c36083c2ebca1948ca6b7f99419210f3b34232289a37761dbe25cefc0443_sc_plug_visual_merged_0" mesh="39e0c36083c2ebca1948ca6b7f99419210f3b34232289a37761dbe25cefc0443_sc_plug_visual_merged_0"/>
                                                    <plugin instance="composite"/>
                                                    <body name="sc_tip_link" pos="0.01165 9.00449e-09 -1.02898e-08" quat="0.499998 -0.5 0.500001 -0.5">
                                                      <inertial pos="0 0 0" mass="0.001" diaginertia="1e-06 1e-06 1e-06"/>
                                                    </body>
                                                  </body>
                                                </body>
                                              </body>
                                            </body>
                                          </body>
                                        </body>
                                      </body>
                                    </body>
                                  </body>
                                </body>
                              </body>
                            </body>
                          </body>
                        </body>
                      </body>
                    </body>
                  </body>
                </body>
              </body>
            </body>
          </body>
        </body>
        <body name="lc_plug_link" pos="-0.041 1.34066e-08 2.63829e-08" quat="0.707109 -1.85087e-08 7.09948e-08 0.707105">
          <inertial pos="0 0.0197 0" quat="0 0.707107 0 0.707107" mass="0.01" diaginertia="1.06153e-07 9.96094e-08 8.49658e-09"/>
          <geom name="cylinder001_collider_cylinder.001" class="world_default" size="0.000625 0.001502" pos="0.003125 0.0197 0" quat="0.707107 0.707107 0 0" type="cylinder" group="3"/>
          <geom name="cylinder_collider_cylinder.001" class="world_default" size="0.000625 0.001502" pos="-0.003125 0.0197 0" quat="0.707107 0.707107 0 0" type="cylinder" group="3"/>
          <geom name="lc_plug_visual" class="world_default" type="mesh" contype="0" conaffinity="0" material="material_79d083415a0beb7006489abaa2f7f67624ecb5cc84df7fd21d83dada2e2c75a0_lc_plug_visual_merged_0" mesh="79d083415a0beb7006489abaa2f7f67624ecb5cc84df7fd21d83dada2e2c75a0_lc_plug_visual_merged_0"/>
          <body name="sfp_module_link" pos="-4.04721e-09 0.0384 1.4723e-09" quat="4.84443e-09 1 -1.31087e-06 -1.37712e-06">
            <inertial pos="0.00024115 0.00702224 0.000553372" quat="0.510037 0.497012 -0.483415 0.50907" mass="0.02" diaginertia="3.07513e-06 2.81054e-06 5.69919e-07"/>
            <geom name="port_collider_box.008" class="world_default" size="0.00071 0.000503 0.0064415" pos="-0.00571 0.018813 -0.003546" quat="0.707107 0.707107 0 0" type="box" group="3"/>
            <geom name="port_collider_box.009" class="world_default" size="0.00071 0.000503 0.0064415" pos="0.00571 0.018813 -0.003546" quat="0.707107 0.707107 0 0" type="box" group="3"/>
            <geom name="body_collider_box" class="world_default" size="0.006875 0.02365 0.0003945" pos="0 0.001 0.00383" type="box" group="3"/>
            <geom name="body_collider_box.001" class="world_default" size="0.006875 0.02365 8.9e-05" pos="0 0.001 -0.004138" type="box" group="3"/>
            <geom name="body_collider_box.002" class="world_default" size="0.000287 0.02365 0.004225" pos="-0.006588 0.001 0" type="box" group="3"/>
            <geom name="body_collider_box.003" class="world_default" size="0.0004055 0.02365 0.004225" pos="0.00647 0.001 0" type="box" group="3"/>
            <geom name="port_collider_box.010" class="world_default" size="0.00642 0.0038815 0.0058645" pos="0 0.01229 0.000119" quat="0.707107 0.707107 0 0" type="box" group="3"/>
            <geom name="port_collider_box002_collider_box" class="world_default" size="0.00642 0.0002045 0.0008005" pos="0 0.024453 -0.004254" quat="0.707107 0.707107 0 0" type="box" group="3"/>
            <geom name="port_collider_box.011" class="world_default" size="0.00125 0.000503 0.0064415" pos="0 0.018813 -0.003546" quat="0.707107 0.707107 0 0" type="box" group="3"/>
            <geom name="sfp_module_visual" class="world_default" type="mesh" contype="0" conaffinity="0" material="material_07ae86fedcbbab3b5759a8a6e79ba15af5075968dd5eac2cb4666913710c9b1a_sfp_module_visual_Body.005" mesh="07ae86fedcbbab3b5759a8a6e79ba15af5075968dd5eac2cb4666913710c9b1a_sfp_module_visual_Body.005"/>
            <geom name="sfp_module_visual_0" class="world_default" type="mesh" contype="0" conaffinity="0" material="material_07ae86fedcbbab3b5759a8a6e79ba15af5075968dd5eac2cb4666913710c9b1a_sfp_module_visual_Body.005_1" mesh="07ae86fedcbbab3b5759a8a6e79ba15af5075968dd5eac2cb4666913710c9b1a_sfp_module_visual_Body.005_1"/>
            <body name="sfp_tip_link" pos="3.24499e-09 -0.0236501 2.38661e-08" quat="0.707105 0.707108 1.60828e-08 -7.22605e-08">
              <inertial pos="0 0 0" mass="0.001" diaginertia="1e-06 1e-06 1e-06"/>
              <geom name="contact_collision" class="world_default" size="0.006875 0.0021125 0.0005" pos="0 0.0021125 -0.0005" type="box" group="3"/>
              <geom name="non_contact_collision" class="world_default" size="0.006875 0.0021125 0.0005" pos="0 -0.0021125 -0.0005" type="box" group="3"/>
            </body>
          </body>
        </body>
      </body>
    </body>
    <body name="static_link">
      <inertial pos="0 0 0" mass="1" diaginertia="1 1 1"/>
    </body>
    <body name="static_link_0">
      <inertial pos="0 0 0" mass="1" diaginertia="1 1 1"/>
    </body>
  </worldbody>

  <contact>
    <exclude body1="cable_end_0" body2="link_1"/>
  </contact>

  <equality>
    <weld body1="ati/tool_link" body2="lc_plug_link" relpose="-0.000711 0.001759 0.168213 0.577301 0.816105 -0.021418 -0.015395" solref="0.002 1" solimp="0.99 0.999 0.001"/>
  </equality>
</mujoco>
